Workbook

Sheet Sheet1
O1: Memory Reference | U1: Carry, Shift, and Skip Functions
A2: Page | B2: Line | C2: Addr | D2: Data | I2: bit 0 | J2: bits 1-3 | K2: bits 4-6 | L2: bits 7-9 | M2: bits 10-12 | N2: bits 13-15 | O2: decimal, bits 0-4 | P2: Op | Q2: AC | R2: OCTAL, D | S2: X | T2: I | U2: AC SRC | V2: AC DEST | W2: FUNCT | X2: SHIFT | Y2: CARRY | Z2: NO LOAD | AA2: SKIP | AB2: Mem Ref Target | AC2: page 0 | AE2: RELATIVE ADDRESS | AF2: D with sign | AG2: indirect | AI2: load/store | AJ2: JMP, JSR, DSZ, ISZ | AL2: FCN | AM2: SHIFT | AN2: CARRY | AO2: LOAD | AP2: SKIP | AS2: IN OR OUT | AT2: AC | AU2: FUNCT | AV2: F | AW2: I/O ADDR | AX2: ADDR SYM | AY2: I/O OP
A3: 6R | B3: 4 | C3: 1 | D3: 5571 | E3: =_xlfn.XLOOKUP(C3,Sheet2!$N$3:$N$1000,Sheet2!$O$3:$O$1000,"") | F3: =IF(AQ3="******************",IF(P3=0,AH3,IF(P3=3,AR3,IF(P3=1,"LDA "&AI3,IF(P3=2,"STA "&AI3,IF(P3=3,AQ3,AK3))))),AQ3) -> IRET | G3: =DEC2OCT((2*(OCT2DEC(I3*100)+OCT2DEC(J3*10)+K3))+INT(L3/4)) -> 13 | H3: =(MOD(L3,4)*100)+(M3*10)+N3 -> 171 | I3: =MOD(INT(D3/100000),10) -> 0 | J3: =MOD(INT(D3/10000),10) -> 0 | K3: =MOD(INT(D3/1000),10) -> 5 | L3: =MOD(INT(D3/100),10) -> 5 | M3: =MOD(INT(D3/10),10) -> 7 | N3: =MOD(D3,10) -> 1 | O3: =INT(K3/4)+(J3*2)+(I3*16) -> 1 | P3: =(I3*4)+INT(J3/2) -> 0 | Q3: =V3 -> 1 | R3: =(MOD(L3,4)*100)+(M3*10)+N3 -> 171 | S3: =(MOD(K3,2)*2)+INT(L3/4) -> 3 | T3: =MOD(INT(K3/2),2) -> 0 | U3: =INT(J3/2) -> 0 | V3: =(MOD(J3,2)*2)+INT(K3/4) -> 1 | W3: =(MOD(K3,4)*2)+INT(L3/4) -> 3 | X3: =MOD(L3,4) -> 1 | Y3: =INT(M3/2) -> 3 | Z3: =MOD(M3,2) -> 1 | AA3: =N3 -> 1 | AB3: =IF(S3=0,AC3,IF(S3=1,IF(AD3="********",AF3,AD3),AF3&","&TEXT(S3,"0"))) -> +171,3 | AC3: =_xlfn.XLOOKUP(R3,Sheet2!$H$3:$H$258,Sheet2!$I$3:$I$258,"-----") -> C11 | AD3: =_xlfn.XLOOKUP(VALUE(AE3),Sheet2!$N$3:$N$1000,Sheet2!$O$3:$O$1000,"********") -> ******** | AE3: =IF(VALUE(AF3)<0,DEC2OCT(OCT2DEC(VALUE(C3))-OCT2DEC(-VALUE(AF3))),DEC2OCT(OCT2DEC(VALUE(C3))+OCT2DEC(VALUE(AF3)))) -> 172 | AF3: =IF(R3<200,"+"&TEXT(R3,"0"),"-"&TEXT(_xlfn.XLOOKUP(R3,Sheet2!$K$3:$K$130,Sheet2!$L$3:$L$130,"-----"),"0")) -> +171 | AG3: =IF(T3=1,"@","") | AH3: =IF(Q3=0,"JMP "&AJ3, IF(Q3=1,"JSR "&AJ3,IF(Q3=2,"ISZ "&AJ3,"DSZ "&AJ3))) -> JSR +171,3 | AI3: =TEXT(Q3,"0")&","&AG3&AB3 -> 1,+171,3 | AJ3: =AG3&AB3 -> +171,3 | AK3: =AL3&AN3&AM3&AO3&" "&TEXT(U3,"0")&","&TEXT(V3,"0")&AP3 -> INCCL# 0,1,SKP | AL3: =IF(W3=0,"COM",IF(W3=1,"NEG",IF(W3=2,"MOV",IF(W3=3,"INC",IF(W3=4,"ADC",IF(W3=5,"SUB",IF(W3=6,"ADD","AND"))))))) -> INC | AM3: =IF(X3=0,"",IF(X3=1,"L",IF(X3=2,"R","S"))) -> L | AN3: =IF(Y3=0,"",IF(Y3=1,"Z",IF(Y3=2,"O","C"))) -> C | AO3: =IF(Z3=1,"#","") -> # | AP3: =IF(AA3=0,"",IF(AA3=1,",SKP",IF(AA3=2,",SZC",IF(AA3=3,",SNC",IF(AA3=4,",SZR",IF(AA3=5,",SNR",IF(AA3=6,",SEZ",",SBN"))))))) -> ,SKP | AQ3: =_xlfn.XLOOKUP(D3,Sheet2!$E$3:$E$101,Sheet2!$F$3:$F$101,"******************") -> IRET | AR3: =IF(AY3=0,"NIO"&AV3&" "&AX3,IF(AY3=7,AZ3&" "&AX3,AS3&" "&TEXT(AT3,"0")&","&AX3)) -> DIBS 1,** | AS3: =IF(AY3=1,"DIA"&AV3,IF(AY3=2,"DOA"&AV3,IF(AY3=3,"DIB"&AV3,IF(AY3=4,"DOB"&AV3,IF(AY3=5,"DIC"&AV3,"DOC"&AV3))))) -> DIBS | AT3: =V3 -> 1 | AU3: =X3 -> 1 | AV3: =IF(AU3=0,"",IF(AU3=1,"S",IF(AU3=2,"C","P"))) -> S | AW3: =M3*10+N3 -> 71 | AX3: =_xlfn.XLOOKUP(AW3,Sheet2!$Q$3:$Q$66,Sheet2!$R$3:$R$66,"**") -> ** | AY3: =W3 -> 3 | AZ3: =IF(AU3=0,"SKPBN",IF(AU3=1,"SKPBZ",IF(AU3=2,"SKPDN","SKPDZ"))) -> SKPBZ
B4: =B3+1 -> 5 | C4: =IF(MOD(C3,10)=7,C3+3,C3+1) -> 2 | D4: 6251 | E4: =_xlfn.XLOOKUP(C4,Sheet2!$N$3:$N$1000,Sheet2!$O$3:$O$1000,"") | F4: =IF(AQ4="******************",IF(P4=0,AH4,IF(P4=3,AR4,IF(P4=1,"LDA "&AI4,IF(P4=2,"STA "&AI4,IF(P4=3,AQ4,AK4))))),AQ4) -> INIT | G4: =DEC2OCT((2*(OCT2DEC(I4*100)+OCT2DEC(J4*10)+K4))+INT(L4/4)) -> 14 | H4: =(MOD(L4,4)*100)+(M4*10)+N4 -> 251 | I4: =MOD(INT(D4/100000),10) -> 0 | J4: =MOD(INT(D4/10000),10) -> 0 | K4: =MOD(INT(D4/1000),10) -> 6 | L4: =MOD(INT(D4/100),10) -> 2 | M4: =MOD(INT(D4/10),10) -> 5 | N4: =MOD(D4,10) -> 1 | O4: =INT(K4/4)+(J4*2)+(I4*16) -> 1 | P4: =(I4*4)+INT(J4/2) -> 0 | Q4: =V4 -> 1 | R4: =(MOD(L4,4)*100)+(M4*10)+N4 -> 251 | S4: =(MOD(K4,2)*2)+INT(L4/4) -> 0 | T4: =MOD(INT(K4/2),2) -> 1 | U4: =INT(J4/2) -> 0 | V4: =(MOD(J4,2)*2)+INT(K4/4) -> 1 | W4: =(MOD(K4,4)*2)+INT(L4/4) -> 4 | X4: =MOD(L4,4) -> 2 | Y4: =INT(M4/2) -> 2 | Z4: =MOD(M4,2) -> 1 | AA4: =N4 -> 1 | AB4: =IF(S4=0,AC4,IF(S4=1,IF(AD4="********",AF4,AD4),AF4&","&TEXT(S4,"0"))) -> I.INI | AC4: =_xlfn.XLOOKUP(R4,Sheet2!$H$3:$H$258,Sheet2!$I$3:$I$258,"-----") -> I.INI | AD4: =_xlfn.XLOOKUP(VALUE(AE4),Sheet2!$N$3:$N$1000,Sheet2!$O$3:$O$1000,"********") -> ******** | AE4: =IF(VALUE(AF4)<0,DEC2OCT(OCT2DEC(VALUE(C4))-OCT2DEC(-VALUE(AF4))),DEC2OCT(OCT2DEC(VALUE(C4))+OCT2DEC(VALUE(AF4)))) -> 7777777653 | AF4: =IF(R4<200,"+"&TEXT(R4,"0"),"-"&TEXT(_xlfn.XLOOKUP(R4,Sheet2!$K$3:$K$130,Sheet2!$L$3:$L$130,"-----"),"0")) -> -127 | AG4: =IF(T4=1,"@","") -> @ | AH4: =IF(Q4=0,"JMP "&AJ4, IF(Q4=1,"JSR "&AJ4,IF(Q4=2,"ISZ "&AJ4,"DSZ "&AJ4))) -> JSR @I.INI | AI4: =TEXT(Q4,"0")&","&AG4&AB4 -> 1,@I.INI | AJ4: =AG4&AB4 -> @I.INI | AK4: =AL4&AN4&AM4&AO4&" "&TEXT(U4,"0")&","&TEXT(V4,"0")&AP4 -> ADCOR# 0,1,SKP | AL4: =IF(W4=0,"COM",IF(W4=1,"NEG",IF(W4=2,"MOV",IF(W4=3,"INC",IF(W4=4,"ADC",IF(W4=5,"SUB",IF(W4=6,"ADD","AND"))))))) -> ADC | AM4: =IF(X4=0,"",IF(X4=1,"L",IF(X4=2,"R","S"))) -> R | AN4: =IF(Y4=0,"",IF(Y4=1,"Z",IF(Y4=2,"O","C"))) -> O | AO4: =IF(Z4=1,"#","") -> # | AP4: =IF(AA4=0,"",IF(AA4=1,",SKP",IF(AA4=2,",SZC",IF(AA4=3,",SNC",IF(AA4=4,",SZR",IF(AA4=5,",SNR",IF(AA4=6,",SEZ",",SBN"))))))) -> ,SKP | AQ4: =_xlfn.XLOOKUP(D4,Sheet2!$E$3:$E$101,Sheet2!$F$3:$F$101,"******************") -> INIT | AR4: =IF(AY4=0,"NIO"&AV4&" "&AX4,IF(AY4=7,AZ4&" "&AX4,AS4&" "&TEXT(AT4,"0")&","&AX4)) -> DOBC 1,** | AS4: =IF(AY4=1,"DIA"&AV4,IF(AY4=2,"DOA"&AV4,IF(AY4=3,"DIB"&AV4,IF(AY4=4,"DOB"&AV4,IF(AY4=5,"DIC"&AV4,"DOC"&AV4))))) -> DOBC | AT4: =V4 -> 1 | AU4: =X4 -> 2 | AV4: =IF(AU4=0,"",IF(AU4=1,"S",IF(AU4=2,"C","P"))) -> C | AW4: =M4*10+N4 -> 51 | AX4: =_xlfn.XLOOKUP(AW4,Sheet2!$Q$3:$Q$66,Sheet2!$R$3:$R$66,"**") -> ** | AY4: =W4 -> 4 | AZ4: =IF(AU4=0,"SKPBN",IF(AU4=1,"SKPBZ",IF(AU4=2,"SKPDN","SKPDZ"))) -> SKPDN
B5: =B4+1 -> 6 | C5: =IF(MOD(C4,10)=7,C4+3,C4+1) -> 3 | D5: 2007 | E5: =_xlfn.XLOOKUP(C5,Sheet2!$N$3:$N$1000,Sheet2!$O$3:$O$1000,"") | F5: =IF(AQ5="******************",IF(P5=0,AH5,IF(P5=3,AR5,IF(P5=1,"LDA "&AI5,IF(P5=2,"STA "&AI5,IF(P5=3,AQ5,AK5))))),AQ5) -> JMP @TS | G5: =DEC2OCT((2*(OCT2DEC(I5*100)+OCT2DEC(J5*10)+K5))+INT(L5/4)) -> 4 | H5: =(MOD(L5,4)*100)+(M5*10)+N5 -> 7 | I5: =MOD(INT(D5/100000),10) -> 0 | J5: =MOD(INT(D5/10000),10) -> 0 | K5: =MOD(INT(D5/1000),10) -> 2 | L5: =MOD(INT(D5/100),10) -> 0 | M5: =MOD(INT(D5/10),10) -> 0 | N5: =MOD(D5,10) -> 7 | O5: =INT(K5/4)+(J5*2)+(I5*16) -> 0 | P5: =(I5*4)+INT(J5/2) -> 0 | Q5: =V5 -> 0 | R5: =(MOD(L5,4)*100)+(M5*10)+N5 -> 7 | S5: =(MOD(K5,2)*2)+INT(L5/4) -> 0 | T5: =MOD(INT(K5/2),2) -> 1 | U5: =INT(J5/2) -> 0 | V5: =(MOD(J5,2)*2)+INT(K5/4) -> 0 | W5: =(MOD(K5,4)*2)+INT(L5/4) -> 4 | X5: =MOD(L5,4) -> 0 | Y5: =INT(M5/2) -> 0 | Z5: =MOD(M5,2) -> 0 | AA5: =N5 -> 7 | AB5: =IF(S5=0,AC5,IF(S5=1,IF(AD5="********",AF5,AD5),AF5&","&TEXT(S5,"0"))) -> TS | AC5: =_xlfn.XLOOKUP(R5,Sheet2!$H$3:$H$258,Sheet2!$I$3:$I$258,"-----") -> TS | AD5: =_xlfn.XLOOKUP(VALUE(AE5),Sheet2!$N$3:$N$1000,Sheet2!$O$3:$O$1000,"********") -> ******** | AE5: =IF(VALUE(AF5)<0,DEC2OCT(OCT2DEC(VALUE(C5))-OCT2DEC(-VALUE(AF5))),DEC2OCT(OCT2DEC(VALUE(C5))+OCT2DEC(VALUE(AF5)))) -> 12 | AF5: =IF(R5<200,"+"&TEXT(R5,"0"),"-"&TEXT(_xlfn.XLOOKUP(R5,Sheet2!$K$3:$K$130,Sheet2!$L$3:$L$130,"-----"),"0")) -> +7 | AG5: =IF(T5=1,"@","") -> @ | AH5: =IF(Q5=0,"JMP "&AJ5, IF(Q5=1,"JSR "&AJ5,IF(Q5=2,"ISZ "&AJ5,"DSZ "&AJ5))) -> JMP @TS | AI5: =TEXT(Q5,"0")&","&AG5&AB5 -> 0,@TS | AJ5: =AG5&AB5 -> @TS | AK5: =AL5&AN5&AM5&AO5&" "&TEXT(U5,"0")&","&TEXT(V5,"0")&AP5 -> ADC 0,0,SBN | AL5: =IF(W5=0,"COM",IF(W5=1,"NEG",IF(W5=2,"MOV",IF(W5=3,"INC",IF(W5=4,"ADC",IF(W5=5,"SUB",IF(W5=6,"ADD","AND"))))))) -> ADC | AM5: =IF(X5=0,"",IF(X5=1,"L",IF(X5=2,"R","S"))) | AN5: =IF(Y5=0,"",IF(Y5=1,"Z",IF(Y5=2,"O","C"))) | AO5: =IF(Z5=1,"#","") | AP5: =IF(AA5=0,"",IF(AA5=1,",SKP",IF(AA5=2,",SZC",IF(AA5=3,",SNC",IF(AA5=4,",SZR",IF(AA5=5,",SNR",IF(AA5=6,",SEZ",",SBN"))))))) -> ,SBN | AQ5: =_xlfn.XLOOKUP(D5,Sheet2!$E$3:$E$101,Sheet2!$F$3:$F$101,"******************") -> ****************** | AR5: =IF(AY5=0,"NIO"&AV5&" "&AX5,IF(AY5=7,AZ5&" "&AX5,AS5&" "&TEXT(AT5,"0")&","&AX5)) -> DOB 0,MCAR | AS5: =IF(AY5=1,"DIA"&AV5,IF(AY5=2,"DOA"&AV5,IF(AY5=3,"DIB"&AV5,IF(AY5=4,"DOB"&AV5,IF(AY5=5,"DIC"&AV5,"DOC"&AV5))))) -> DOB | AT5: =V5 -> 0 | AU5: =X5 -> 0 | AV5: =IF(AU5=0,"",IF(AU5=1,"S",IF(AU5=2,"C","P"))) | AW5: =M5*10+N5 -> 7 | AX5: =_xlfn.XLOOKUP(AW5,Sheet2!$Q$3:$Q$66,Sheet2!$R$3:$R$66,"**") -> MCAR | AY5: =W5 -> 4 | AZ5: =IF(AU5=0,"SKPBN",IF(AU5=1,"SKPBZ",IF(AU5=2,"SKPDN","SKPDZ"))) -> SKPBN
B6: =B5+1 -> 7 | C6: =IF(MOD(C5,10)=7,C5+3,C5+1) -> 4 | D6: 2244 | E6: =_xlfn.XLOOKUP(C6,Sheet2!$N$3:$N$1000,Sheet2!$O$3:$O$1000,"") | F6: =IF(AQ6="******************",IF(P6=0,AH6,IF(P6=3,AR6,IF(P6=1,"LDA "&AI6,IF(P6=2,"STA "&AI6,IF(P6=3,AQ6,AK6))))),AQ6) -> JMP @IS33 | G6: =DEC2OCT((2*(OCT2DEC(I6*100)+OCT2DEC(J6*10)+K6))+INT(L6/4)) -> 4 | H6: =(MOD(L6,4)*100)+(M6*10)+N6 -> 244 | I6: =MOD(INT(D6/100000),10) -> 0 | J6: =MOD(INT(D6/10000),10) -> 0 | K6: =MOD(INT(D6/1000),10) -> 2 | L6: =MOD(INT(D6/100),10) -> 2 | M6: =MOD(INT(D6/10),10) -> 4 | N6: =MOD(D6,10) -> 4 | O6: =INT(K6/4)+(J6*2)+(I6*16) -> 0 | P6: =(I6*4)+INT(J6/2) -> 0 | Q6: =V6 -> 0 | R6: =(MOD(L6,4)*100)+(M6*10)+N6 -> 244 | S6: =(MOD(K6,2)*2)+INT(L6/4) -> 0 | T6: =MOD(INT(K6/2),2) -> 1 | U6: =INT(J6/2) -> 0 | V6: =(MOD(J6,2)*2)+INT(K6/4) -> 0 | W6: =(MOD(K6,4)*2)+INT(L6/4) -> 4 | X6: =MOD(L6,4) -> 2 | Y6: =INT(M6/2) -> 2 | Z6: =MOD(M6,2) -> 0 | AA6: =N6 -> 4 | AB6: =IF(S6=0,AC6,IF(S6=1,IF(AD6="********",AF6,AD6),AF6&","&TEXT(S6,"0"))) -> IS33 | AC6: =_xlfn.XLOOKUP(R6,Sheet2!$H$3:$H$258,Sheet2!$I$3:$I$258,"-----") -> IS33 | AD6: =_xlfn.XLOOKUP(VALUE(AE6),Sheet2!$N$3:$N$1000,Sheet2!$O$3:$O$1000,"********") -> ******** | AE6: =IF(VALUE(AF6)<0,DEC2OCT(OCT2DEC(VALUE(C6))-OCT2DEC(-VALUE(AF6))),DEC2OCT(OCT2DEC(VALUE(C6))+OCT2DEC(VALUE(AF6)))) -> 7777777650 | AF6: =IF(R6<200,"+"&TEXT(R6,"0"),"-"&TEXT(_xlfn.XLOOKUP(R6,Sheet2!$K$3:$K$130,Sheet2!$L$3:$L$130,"-----"),"0")) -> -134 | AG6: =IF(T6=1,"@","") -> @ | AH6: =IF(Q6=0,"JMP "&AJ6, IF(Q6=1,"JSR "&AJ6,IF(Q6=2,"ISZ "&AJ6,"DSZ "&AJ6))) -> JMP @IS33 | AI6: =TEXT(Q6,"0")&","&AG6&AB6 -> 0,@IS33 | AJ6: =AG6&AB6 -> @IS33 | AK6: =AL6&AN6&AM6&AO6&" "&TEXT(U6,"0")&","&TEXT(V6,"0")&AP6 -> ADCOR 0,0,SZR | AL6: =IF(W6=0,"COM",IF(W6=1,"NEG",IF(W6=2,"MOV",IF(W6=3,"INC",IF(W6=4,"ADC",IF(W6=5,"SUB",IF(W6=6,"ADD","AND"))))))) -> ADC | AM6: =IF(X6=0,"",IF(X6=1,"L",IF(X6=2,"R","S"))) -> R | AN6: =IF(Y6=0,"",IF(Y6=1,"Z",IF(Y6=2,"O","C"))) -> O | AO6: =IF(Z6=1,"#","") | AP6: =IF(AA6=0,"",IF(AA6=1,",SKP",IF(AA6=2,",SZC",IF(AA6=3,",SNC",IF(AA6=4,",SZR",IF(AA6=5,",SNR",IF(AA6=6,",SEZ",",SBN"))))))) -> ,SZR | AQ6: =_xlfn.XLOOKUP(D6,Sheet2!$E$3:$E$101,Sheet2!$F$3:$F$101,"******************") -> ****************** | AR6: =IF(AY6=0,"NIO"&AV6&" "&AX6,IF(AY6=7,AZ6&" "&AX6,AS6&" "&TEXT(AT6,"0")&","&AX6)) -> DOBC 0,** | AS6: =IF(AY6=1,"DIA"&AV6,IF(AY6=2,"DOA"&AV6,IF(AY6=3,"DIB"&AV6,IF(AY6=4,"DOB"&AV6,IF(AY6=5,"DIC"&AV6,"DOC"&AV6))))) -> DOBC | AT6: =V6 -> 0 | AU6: =X6 -> 2 | AV6: =IF(AU6=0,"",IF(AU6=1,"S",IF(AU6=2,"C","P"))) -> C | AW6: =M6*10+N6 -> 44 | AX6: =_xlfn.XLOOKUP(AW6,Sheet2!$Q$3:$Q$66,Sheet2!$R$3:$R$66,"**") -> ** | AY6: =W6 -> 4 | AZ6: =IF(AU6=0,"SKPBN",IF(AU6=1,"SKPBZ",IF(AU6=2,"SKPDN","SKPDZ"))) -> SKPDN
B7: =B6+1 -> 8 | C7: =IF(MOD(C6,10)=7,C6+3,C6+1) -> 5 | D7: 2245 | E7: =_xlfn.XLOOKUP(C7,Sheet2!$N$3:$N$1000,Sheet2!$O$3:$O$1000,"") | F7: =IF(AQ7="******************",IF(P7=0,AH7,IF(P7=3,AR7,IF(P7=1,"LDA "&AI7,IF(P7=2,"STA "&AI7,IF(P7=3,AQ7,AK7))))),AQ7) -> JMP @IS73 | G7: =DEC2OCT((2*(OCT2DEC(I7*100)+OCT2DEC(J7*10)+K7))+INT(L7/4)) -> 4 | H7: =(MOD(L7,4)*100)+(M7*10)+N7 -> 245 | I7: =MOD(INT(D7/100000),10) -> 0 | J7: =MOD(INT(D7/10000),10) -> 0 | K7: =MOD(INT(D7/1000),10) -> 2 | L7: =MOD(INT(D7/100),10) -> 2 | M7: =MOD(INT(D7/10),10) -> 4 | N7: =MOD(D7,10) -> 5 | O7: =INT(K7/4)+(J7*2)+(I7*16) -> 0 | P7: =(I7*4)+INT(J7/2) -> 0 | Q7: =V7 -> 0 | R7: =(MOD(L7,4)*100)+(M7*10)+N7 -> 245 | S7: =(MOD(K7,2)*2)+INT(L7/4) -> 0 | T7: =MOD(INT(K7/2),2) -> 1 | U7: =INT(J7/2) -> 0 | V7: =(MOD(J7,2)*2)+INT(K7/4) -> 0 | W7: =(MOD(K7,4)*2)+INT(L7/4) -> 4 | X7: =MOD(L7,4) -> 2 | Y7: =INT(M7/2) -> 2 | Z7: =MOD(M7,2) -> 0 | AA7: =N7 -> 5 | AB7: =IF(S7=0,AC7,IF(S7=1,IF(AD7="********",AF7,AD7),AF7&","&TEXT(S7,"0"))) -> IS73 | AC7: =_xlfn.XLOOKUP(R7,Sheet2!$H$3:$H$258,Sheet2!$I$3:$I$258,"-----") -> IS73 | AD7: =_xlfn.XLOOKUP(VALUE(AE7),Sheet2!$N$3:$N$1000,Sheet2!$O$3:$O$1000,"********") -> ******** | AE7: =IF(VALUE(AF7)<0,DEC2OCT(OCT2DEC(VALUE(C7))-OCT2DEC(-VALUE(AF7))),DEC2OCT(OCT2DEC(VALUE(C7))+OCT2DEC(VALUE(AF7)))) -> 7777777652 | AF7: =IF(R7<200,"+"&TEXT(R7,"0"),"-"&TEXT(_xlfn.XLOOKUP(R7,Sheet2!$K$3:$K$130,Sheet2!$L$3:$L$130,"-----"),"0")) -> -133 | AG7: =IF(T7=1,"@","") -> @ | AH7: =IF(Q7=0,"JMP "&AJ7, IF(Q7=1,"JSR "&AJ7,IF(Q7=2,"ISZ "&AJ7,"DSZ "&AJ7))) -> JMP @IS73 | AI7: =TEXT(Q7,"0")&","&AG7&AB7 -> 0,@IS73 | AJ7: =AG7&AB7 -> @IS73 | AK7: =AL7&AN7&AM7&AO7&" "&TEXT(U7,"0")&","&TEXT(V7,"0")&AP7 -> ADCOR 0,0,SNR | AL7: =IF(W7=0,"COM",IF(W7=1,"NEG",IF(W7=2,"MOV",IF(W7=3,"INC",IF(W7=4,"ADC",IF(W7=5,"SUB",IF(W7=6,"ADD","AND"))))))) -> ADC | AM7: =IF(X7=0,"",IF(X7=1,"L",IF(X7=2,"R","S"))) -> R | AN7: =IF(Y7=0,"",IF(Y7=1,"Z",IF(Y7=2,"O","C"))) -> O | AO7: =IF(Z7=1,"#","") | AP7: =IF(AA7=0,"",IF(AA7=1,",SKP",IF(AA7=2,",SZC",IF(AA7=3,",SNC",IF(AA7=4,",SZR",IF(AA7=5,",SNR",IF(AA7=6,",SEZ",",SBN"))))))) -> ,SNR | AQ7: =_xlfn.XLOOKUP(D7,Sheet2!$E$3:$E$101,Sheet2!$F$3:$F$101,"******************") -> ****************** | AR7: =IF(AY7=0,"NIO"&AV7&" "&AX7,IF(AY7=7,AZ7&" "&AX7,AS7&" "&TEXT(AT7,"0")&","&AX7)) -> DOBC 0,** | AS7: =IF(AY7=1,"DIA"&AV7,IF(AY7=2,"DOA"&AV7,IF(AY7=3,"DIB"&AV7,IF(AY7=4,"DOB"&AV7,IF(AY7=5,"DIC"&AV7,"DOC"&AV7))))) -> DOBC | AT7: =V7 -> 0 | AU7: =X7 -> 2 | AV7: =IF(AU7=0,"",IF(AU7=1,"S",IF(AU7=2,"C","P"))) -> C | AW7: =M7*10+N7 -> 45 | AX7: =_xlfn.XLOOKUP(AW7,Sheet2!$Q$3:$Q$66,Sheet2!$R$3:$R$66,"**") -> ** | AY7: =W7 -> 4 | AZ7: =IF(AU7=0,"SKPBN",IF(AU7=1,"SKPBZ",IF(AU7=2,"SKPDN","SKPDZ"))) -> SKPDN
B8: =B7+1 -> 9 | C8: =IF(MOD(C7,10)=7,C7+3,C7+1) -> 6 | D8: 2010 | E8: =_xlfn.XLOOKUP(C8,Sheet2!$N$3:$N$1000,Sheet2!$O$3:$O$1000,"") | F8: =IF(AQ8="******************",IF(P8=0,AH8,IF(P8=3,AR8,IF(P8=1,"LDA "&AI8,IF(P8=2,"STA "&AI8,IF(P8=3,AQ8,AK8))))),AQ8) -> JMP @IRDSK | G8: =DEC2OCT((2*(OCT2DEC(I8*100)+OCT2DEC(J8*10)+K8))+INT(L8/4)) -> 4 | H8: =(MOD(L8,4)*100)+(M8*10)+N8 -> 10 | I8: =MOD(INT(D8/100000),10) -> 0 | J8: =MOD(INT(D8/10000),10) -> 0 | K8: =MOD(INT(D8/1000),10) -> 2 | L8: =MOD(INT(D8/100),10) -> 0 | M8: =MOD(INT(D8/10),10) -> 1 | N8: =MOD(D8,10) -> 0 | O8: =INT(K8/4)+(J8*2)+(I8*16) -> 0 | P8: =(I8*4)+INT(J8/2) -> 0 | Q8: =V8 -> 0 | R8: =(MOD(L8,4)*100)+(M8*10)+N8 -> 10 | S8: =(MOD(K8,2)*2)+INT(L8/4) -> 0 | T8: =MOD(INT(K8/2),2) -> 1 | U8: =INT(J8/2) -> 0 | V8: =(MOD(J8,2)*2)+INT(K8/4) -> 0 | W8: =(MOD(K8,4)*2)+INT(L8/4) -> 4 | X8: =MOD(L8,4) -> 0 | Y8: =INT(M8/2) -> 0 | Z8: =MOD(M8,2) -> 1 | AA8: =N8 -> 0 | AB8: =IF(S8=0,AC8,IF(S8=1,IF(AD8="********",AF8,AD8),AF8&","&TEXT(S8,"0"))) -> IRDSK | AC8: =_xlfn.XLOOKUP(R8,Sheet2!$H$3:$H$258,Sheet2!$I$3:$I$258,"-----") -> IRDSK | AD8: =_xlfn.XLOOKUP(VALUE(AE8),Sheet2!$N$3:$N$1000,Sheet2!$O$3:$O$1000,"********") -> ******** | AE8: =IF(VALUE(AF8)<0,DEC2OCT(OCT2DEC(VALUE(C8))-OCT2DEC(-VALUE(AF8))),DEC2OCT(OCT2DEC(VALUE(C8))+OCT2DEC(VALUE(AF8)))) -> 16 | AF8: =IF(R8<200,"+"&TEXT(R8,"0"),"-"&TEXT(_xlfn.XLOOKUP(R8,Sheet2!$K$3:$K$130,Sheet2!$L$3:$L$130,"-----"),"0")) -> +10 | AG8: =IF(T8=1,"@","") -> @ | AH8: =IF(Q8=0,"JMP "&AJ8, IF(Q8=1,"JSR "&AJ8,IF(Q8=2,"ISZ "&AJ8,"DSZ "&AJ8))) -> JMP @IRDSK | AI8: =TEXT(Q8,"0")&","&AG8&AB8 -> 0,@IRDSK | AJ8: =AG8&AB8 -> @IRDSK | AK8: =AL8&AN8&AM8&AO8&" "&TEXT(U8,"0")&","&TEXT(V8,"0")&AP8 -> ADC# 0,0 | AL8: =IF(W8=0,"COM",IF(W8=1,"NEG",IF(W8=2,"MOV",IF(W8=3,"INC",IF(W8=4,"ADC",IF(W8=5,"SUB",IF(W8=6,"ADD","AND"))))))) -> ADC | AM8: =IF(X8=0,"",IF(X8=1,"L",IF(X8=2,"R","S"))) | AN8: =IF(Y8=0,"",IF(Y8=1,"Z",IF(Y8=2,"O","C"))) | AO8: =IF(Z8=1,"#","") -> # | AP8: =IF(AA8=0,"",IF(AA8=1,",SKP",IF(AA8=2,",SZC",IF(AA8=3,",SNC",IF(AA8=4,",SZR",IF(AA8=5,",SNR",IF(AA8=6,",SEZ",",SBN"))))))) | AQ8: =_xlfn.XLOOKUP(D8,Sheet2!$E$3:$E$101,Sheet2!$F$3:$F$101,"******************") -> ****************** | AR8: =IF(AY8=0,"NIO"&AV8&" "&AX8,IF(AY8=7,AZ8&" "&AX8,AS8&" "&TEXT(AT8,"0")&","&AX8)) -> DOB 0,TTI | AS8: =IF(AY8=1,"DIA"&AV8,IF(AY8=2,"DOA"&AV8,IF(AY8=3,"DIB"&AV8,IF(AY8=4,"DOB"&AV8,IF(AY8=5,"DIC"&AV8,"DOC"&AV8))))) -> DOB | AT8: =V8 -> 0 | AU8: =X8 -> 0 | AV8: =IF(AU8=0,"",IF(AU8=1,"S",IF(AU8=2,"C","P"))) | AW8: =M8*10+N8 -> 10 | AX8: =_xlfn.XLOOKUP(AW8,Sheet2!$Q$3:$Q$66,Sheet2!$R$3:$R$66,"**") -> TTI | AY8: =W8 -> 4 | AZ8: =IF(AU8=0,"SKPBN",IF(AU8=1,"SKPBZ",IF(AU8=2,"SKPDN","SKPDZ"))) -> SKPBN
B9: =B8+1 -> 10 | C9: =IF(MOD(C8,10)=7,C8+3,C8+1) -> 7 | D9: 500 | E9: =_xlfn.XLOOKUP(C9,Sheet2!$N$3:$N$1000,Sheet2!$O$3:$O$1000,"") | G9: =DEC2OCT((2*(OCT2DEC(I9*100)+OCT2DEC(J9*10)+K9))+INT(L9/4)) -> 1 | H9: =(MOD(L9,4)*100)+(M9*10)+N9 -> 100 | I9: =MOD(INT(D9/100000),10) -> 0 | J9: =MOD(INT(D9/10000),10) -> 0 | K9: =MOD(INT(D9/1000),10) -> 0 | L9: =MOD(INT(D9/100),10) -> 5 | M9: =MOD(INT(D9/10),10) -> 0 | N9: =MOD(D9,10) -> 0 | O9: =INT(K9/4)+(J9*2)+(I9*16) -> 0 | P9: =(I9*4)+INT(J9/2) -> 0 | Q9: =V9 -> 0 | R9: =(MOD(L9,4)*100)+(M9*10)+N9 -> 100 | S9: =(MOD(K9,2)*2)+INT(L9/4) -> 1 | T9: =MOD(INT(K9/2),2) -> 0 | U9: =INT(J9/2) -> 0 | V9: =(MOD(J9,2)*2)+INT(K9/4) -> 0 | W9: =(MOD(K9,4)*2)+INT(L9/4) -> 1 | X9: =MOD(L9,4) -> 1 | Y9: =INT(M9/2) -> 0 | Z9: =MOD(M9,2) -> 0 | AA9: =N9 -> 0 | AB9: =IF(S9=0,AC9,IF(S9=1,IF(AD9="********",AF9,AD9),AF9&","&TEXT(S9,"0"))) -> +100 | AC9: =_xlfn.XLOOKUP(R9,Sheet2!$H$3:$H$258,Sheet2!$I$3:$I$258,"-----") -> ZB11 | AD9: =_xlfn.XLOOKUP(VALUE(AE9),Sheet2!$N$3:$N$1000,Sheet2!$O$3:$O$1000,"********") -> ******** | AE9: =IF(VALUE(AF9)<0,DEC2OCT(OCT2DEC(VALUE(C9))-OCT2DEC(-VALUE(AF9))),DEC2OCT(OCT2DEC(VALUE(C9))+OCT2DEC(VALUE(AF9)))) -> 107 | AF9: =IF(R9<200,"+"&TEXT(R9,"0"),"-"&TEXT(_xlfn.XLOOKUP(R9,Sheet2!$K$3:$K$130,Sheet2!$L$3:$L$130,"-----"),"0")) -> +100 | AG9: =IF(T9=1,"@","") | AH9: =IF(Q9=0,"JMP "&AJ9, IF(Q9=1,"JSR "&AJ9,IF(Q9=2,"ISZ "&AJ9,"DSZ "&AJ9))) -> JMP +100 | AI9: =TEXT(Q9,"0")&","&AG9&AB9 -> 0,+100 | AJ9: =AG9&AB9 -> +100 | AK9: =AL9&AN9&AM9&AO9&" "&TEXT(U9,"0")&","&TEXT(V9,"0")&AP9 -> NEGL 0,0 | AL9: =IF(W9=0,"COM",IF(W9=1,"NEG",IF(W9=2,"MOV",IF(W9=3,"INC",IF(W9=4,"ADC",IF(W9=5,"SUB",IF(W9=6,"ADD","AND"))))))) -> NEG | AM9: =IF(X9=0,"",IF(X9=1,"L",IF(X9=2,"R","S"))) -> L | AN9: =IF(Y9=0,"",IF(Y9=1,"Z",IF(Y9=2,"O","C"))) | AO9: =IF(Z9=1,"#","") | AP9: =IF(AA9=0,"",IF(AA9=1,",SKP",IF(AA9=2,",SZC",IF(AA9=3,",SNC",IF(AA9=4,",SZR",IF(AA9=5,",SNR",IF(AA9=6,",SEZ",",SBN"))))))) | AQ9: =_xlfn.XLOOKUP(D9,Sheet2!$E$3:$E$101,Sheet2!$F$3:$F$101,"******************") -> ****************** | AR9: =IF(AY9=0,"NIO"&AV9&" "&AX9,IF(AY9=7,AZ9&" "&AX9,AS9&" "&TEXT(AT9,"0")&","&AX9)) -> DIAS 0,0 | AS9: =IF(AY9=1,"DIA"&AV9,IF(AY9=2,"DOA"&AV9,IF(AY9=3,"DIB"&AV9,IF(AY9=4,"DOB"&AV9,IF(AY9=5,"DIC"&AV9,"DOC"&AV9))))) -> DIAS | AT9: =V9 -> 0 | AU9: =X9 -> 1 | AV9: =IF(AU9=0,"",IF(AU9=1,"S",IF(AU9=2,"C","P"))) -> S | AW9: =M9*10+N9 -> 0 | AX9: =_xlfn.XLOOKUP(AW9,Sheet2!$Q$3:$Q$66,Sheet2!$R$3:$R$66,"**") -> 0 | AY9: =W9 -> 1 | AZ9: =IF(AU9=0,"SKPBN",IF(AU9=1,"SKPBZ",IF(AU9=2,"SKPDN","SKPDZ"))) -> SKPBZ
B10: =B9+1 -> 11 | C10: =IF(MOD(C9,10)=7,C9+3,C9+1) -> 10 | D10: 4513 | E10: =_xlfn.XLOOKUP(C10,Sheet2!$N$3:$N$1000,Sheet2!$O$3:$O$1000,"") | G10: =DEC2OCT((2*(OCT2DEC(I10*100)+OCT2DEC(J10*10)+K10))+INT(L10/4)) -> 11 | H10: =(MOD(L10,4)*100)+(M10*10)+N10 -> 113 | I10: =MOD(INT(D10/100000),10) -> 0 | J10: =MOD(INT(D10/10000),10) -> 0 | K10: =MOD(INT(D10/1000),10) -> 4 | L10: =MOD(INT(D10/100),10) -> 5 | M10: =MOD(INT(D10/10),10) -> 1 | N10: =MOD(D10,10) -> 3 | O10: =INT(K10/4)+(J10*2)+(I10*16) -> 1 | P10: =(I10*4)+INT(J10/2) -> 0 | Q10: =V10 -> 1 | R10: =(MOD(L10,4)*100)+(M10*10)+N10 -> 113 | S10: =(MOD(K10,2)*2)+INT(L10/4) -> 1 | T10: =MOD(INT(K10/2),2) -> 0 | U10: =INT(J10/2) -> 0 | V10: =(MOD(J10,2)*2)+INT(K10/4) -> 1 | W10: =(MOD(K10,4)*2)+INT(L10/4) -> 1 | X10: =MOD(L10,4) -> 1 | Y10: =INT(M10/2) -> 0 | Z10: =MOD(M10,2) -> 1 | AA10: =N10 -> 3 | AB10: =IF(S10=0,AC10,IF(S10=1,IF(AD10="********",AF10,AD10),AF10&","&TEXT(S10,"0"))) -> +113 | AC10: =_xlfn.XLOOKUP(R10,Sheet2!$H$3:$H$258,Sheet2!$I$3:$I$258,"-----") -> TRCL | AD10: =_xlfn.XLOOKUP(VALUE(AE10),Sheet2!$N$3:$N$1000,Sheet2!$O$3:$O$1000,"********") -> ******** | AE10: =IF(VALUE(AF10)<0,DEC2OCT(OCT2DEC(VALUE(C10))-OCT2DEC(-VALUE(AF10))),DEC2OCT(OCT2DEC(VALUE(C10))+OCT2DEC(VALUE(AF10)))) -> 123 | AF10: =IF(R10<200,"+"&TEXT(R10,"0"),"-"&TEXT(_xlfn.XLOOKUP(R10,Sheet2!$K$3:$K$130,Sheet2!$L$3:$L$130,"-----"),"0")) -> +113 | AG10: =IF(T10=1,"@","") | AH10: =IF(Q10=0,"JMP "&AJ10, IF(Q10=1,"JSR "&AJ10,IF(Q10=2,"ISZ "&AJ10,"DSZ "&AJ10))) -> JSR +113 | AI10: =TEXT(Q10,"0")&","&AG10&AB10 -> 1,+113 | AJ10: =AG10&AB10 -> +113 | AK10: =AL10&AN10&AM10&AO10&" "&TEXT(U10,"0")&","&TEXT(V10,"0")&AP10 -> NEGL# 0,1,SNC | AL10: =IF(W10=0,"COM",IF(W10=1,"NEG",IF(W10=2,"MOV",IF(W10=3,"INC",IF(W10=4,"ADC",IF(W10=5,"SUB",IF(W10=6,"ADD","AND"))))))) -> NEG | AM10: =IF(X10=0,"",IF(X10=1,"L",IF(X10=2,"R","S"))) -> L | AN10: =IF(Y10=0,"",IF(Y10=1,"Z",IF(Y10=2,"O","C"))) | AO10: =IF(Z10=1,"#","") -> # | AP10: =IF(AA10=0,"",IF(AA10=1,",SKP",IF(AA10=2,",SZC",IF(AA10=3,",SNC",IF(AA10=4,",SZR",IF(AA10=5,",SNR",IF(AA10=6,",SEZ",",SBN"))))))) -> ,SNC | AQ10: =_xlfn.XLOOKUP(D10,Sheet2!$E$3:$E$101,Sheet2!$F$3:$F$101,"******************") -> ****************** | AR10: =IF(AY10=0,"NIO"&AV10&" "&AX10,IF(AY10=7,AZ10&" "&AX10,AS10&" "&TEXT(AT10,"0")&","&AX10)) -> DIAS 1,PTP | AS10: =IF(AY10=1,"DIA"&AV10,IF(AY10=2,"DOA"&AV10,IF(AY10=3,"DIB"&AV10,IF(AY10=4,"DOB"&AV10,IF(AY10=5,"DIC"&AV10,"DOC"&AV10))))) -> DIAS | AT10: =V10 -> 1 | AU10: =X10 -> 1 | AV10: =IF(AU10=0,"",IF(AU10=1,"S",IF(AU10=2,"C","P"))) -> S | AW10: =M10*10+N10 -> 13 | AX10: =_xlfn.XLOOKUP(AW10,Sheet2!$Q$3:$Q$66,Sheet2!$R$3:$R$66,"**") -> PTP | AY10: =W10 -> 1 | AZ10: =IF(AU10=0,"SKPBN",IF(AU10=1,"SKPBZ",IF(AU10=2,"SKPDN","SKPDZ"))) -> SKPBZ
B11: =B10+1 -> 12 | C11: =IF(MOD(C10,10)=7,C10+3,C10+1) -> 11 | D11: 2 | E11: =_xlfn.XLOOKUP(C11,Sheet2!$N$3:$N$1000,Sheet2!$O$3:$O$1000,"") | G11: =DEC2OCT((2*(OCT2DEC(I11*100)+OCT2DEC(J11*10)+K11))+INT(L11/4)) -> 0 | H11: =(MOD(L11,4)*100)+(M11*10)+N11 -> 2 | I11: =MOD(INT(D11/100000),10) -> 0 | J11: =MOD(INT(D11/10000),10) -> 0 | K11: =MOD(INT(D11/1000),10) -> 0 | L11: =MOD(INT(D11/100),10) -> 0 | M11: =MOD(INT(D11/10),10) -> 0 | N11: =MOD(D11,10) -> 2 | O11: =INT(K11/4)+(J11*2)+(I11*16) -> 0 | P11: =(I11*4)+INT(J11/2) -> 0 | Q11: =V11 -> 0 | R11: =(MOD(L11,4)*100)+(M11*10)+N11 -> 2 | S11: =(MOD(K11,2)*2)+INT(L11/4) -> 0 | T11: =MOD(INT(K11/2),2) -> 0 | U11: =INT(J11/2) -> 0 | V11: =(MOD(J11,2)*2)+INT(K11/4) -> 0 | W11: =(MOD(K11,4)*2)+INT(L11/4) -> 0 | X11: =MOD(L11,4) -> 0 | Y11: =INT(M11/2) -> 0 | Z11: =MOD(M11,2) -> 0 | AA11: =N11 -> 2 | AB11: =IF(S11=0,AC11,IF(S11=1,IF(AD11="********",AF11,AD11),AF11&","&TEXT(S11,"0"))) -> ***** | AC11: =_xlfn.XLOOKUP(R11,Sheet2!$H$3:$H$258,Sheet2!$I$3:$I$258,"-----") -> ***** | AD11: =_xlfn.XLOOKUP(VALUE(AE11),Sheet2!$N$3:$N$1000,Sheet2!$O$3:$O$1000,"********") -> ******** | AE11: =IF(VALUE(AF11)<0,DEC2OCT(OCT2DEC(VALUE(C11))-OCT2DEC(-VALUE(AF11))),DEC2OCT(OCT2DEC(VALUE(C11))+OCT2DEC(VALUE(AF11)))) -> 13 | AF11: =IF(R11<200,"+"&TEXT(R11,"0"),"-"&TEXT(_xlfn.XLOOKUP(R11,Sheet2!$K$3:$K$130,Sheet2!$L$3:$L$130,"-----"),"0")) -> +2 | AG11: =IF(T11=1,"@","") | AH11: =IF(Q11=0,"JMP "&AJ11, IF(Q11=1,"JSR "&AJ11,IF(Q11=2,"ISZ "&AJ11,"DSZ "&AJ11))) -> JMP ***** | AI11: =TEXT(Q11,"0")&","&AG11&AB11 -> 0,***** | AJ11: =AG11&AB11 -> ***** | AK11: =AL11&AN11&AM11&AO11&" "&TEXT(U11,"0")&","&TEXT(V11,"0")&AP11 -> COM 0,0,SZC | AL11: =IF(W11=0,"COM",IF(W11=1,"NEG",IF(W11=2,"MOV",IF(W11=3,"INC",IF(W11=4,"ADC",IF(W11=5,"SUB",IF(W11=6,"ADD","AND"))))))) -> COM | AM11: =IF(X11=0,"",IF(X11=1,"L",IF(X11=2,"R","S"))) | AN11: =IF(Y11=0,"",IF(Y11=1,"Z",IF(Y11=2,"O","C"))) | AO11: =IF(Z11=1,"#","") | AP11: =IF(AA11=0,"",IF(AA11=1,",SKP",IF(AA11=2,",SZC",IF(AA11=3,",SNC",IF(AA11=4,",SZR",IF(AA11=5,",SNR",IF(AA11=6,",SEZ",",SBN"))))))) -> ,SZC | AQ11: =_xlfn.XLOOKUP(D11,Sheet2!$E$3:$E$101,Sheet2!$F$3:$F$101,"******************") -> ****************** | AR11: =IF(AY11=0,"NIO"&AV11&" "&AX11,IF(AY11=7,AZ11&" "&AX11,AS11&" "&TEXT(AT11,"0")&","&AX11)) -> NIO MAP0 | AS11: =IF(AY11=1,"DIA"&AV11,IF(AY11=2,"DOA"&AV11,IF(AY11=3,"DIB"&AV11,IF(AY11=4,"DOB"&AV11,IF(AY11=5,"DIC"&AV11,"DOC"&AV11))))) -> DOC | AT11: =V11 -> 0 | AU11: =X11 -> 0 | AV11: =IF(AU11=0,"",IF(AU11=1,"S",IF(AU11=2,"C","P"))) | AW11: =M11*10+N11 -> 2 | AX11: =_xlfn.XLOOKUP(AW11,Sheet2!$Q$3:$Q$66,Sheet2!$R$3:$R$66,"**") -> MAP0 | AY11: =W11 -> 0 | AZ11: =IF(AU11=0,"SKPBN",IF(AU11=1,"SKPBZ",IF(AU11=2,"SKPDN","SKPDZ"))) -> SKPBN
B12: 15 | C12: 45 | D12: 46 | E12: =_xlfn.XLOOKUP(C12,Sheet2!$N$3:$N$1000,Sheet2!$O$3:$O$1000,"") | G12: =DEC2OCT((2*(OCT2DEC(I12*100)+OCT2DEC(J12*10)+K12))+INT(L12/4)) -> 0 | H12: =(MOD(L12,4)*100)+(M12*10)+N12 -> 46 | I12: =MOD(INT(D12/100000),10) -> 0 | J12: =MOD(INT(D12/10000),10) -> 0 | K12: =MOD(INT(D12/1000),10) -> 0 | L12: =MOD(INT(D12/100),10) -> 0 | M12: =MOD(INT(D12/10),10) -> 4 | N12: =MOD(D12,10) -> 6 | O12: =INT(K12/4)+(J12*2)+(I12*16) -> 0 | P12: =(I12*4)+INT(J12/2) -> 0 | Q12: =V12 -> 0 | R12: =(MOD(L12,4)*100)+(M12*10)+N12 -> 46 | S12: =(MOD(K12,2)*2)+INT(L12/4) -> 0 | T12: =MOD(INT(K12/2),2) -> 0 | U12: =INT(J12/2) -> 0 | V12: =(MOD(J12,2)*2)+INT(K12/4) -> 0 | W12: =(MOD(K12,4)*2)+INT(L12/4) -> 0 | X12: =MOD(L12,4) -> 0 | Y12: =INT(M12/2) -> 2 | Z12: =MOD(M12,2) -> 0 | AA12: =N12 -> 6 | AB12: =IF(S12=0,AC12,IF(S12=1,IF(AD12="********",AF12,AD12),AF12&","&TEXT(S12,"0"))) -> EGGS | AC12: =_xlfn.XLOOKUP(R12,Sheet2!$H$3:$H$258,Sheet2!$I$3:$I$258,"-----") -> EGGS | AD12: =_xlfn.XLOOKUP(VALUE(AE12),Sheet2!$N$3:$N$1000,Sheet2!$O$3:$O$1000,"********") -> ******** | AE12: =IF(VALUE(AF12)<0,DEC2OCT(OCT2DEC(VALUE(C12))-OCT2DEC(-VALUE(AF12))),DEC2OCT(OCT2DEC(VALUE(C12))+OCT2DEC(VALUE(AF12)))) -> 113 | AF12: =IF(R12<200,"+"&TEXT(R12,"0"),"-"&TEXT(_xlfn.XLOOKUP(R12,Sheet2!$K$3:$K$130,Sheet2!$L$3:$L$130,"-----"),"0")) -> +46 | AG12: =IF(T12=1,"@","") | AH12: =IF(Q12=0,"JMP "&AJ12, IF(Q12=1,"JSR "&AJ12,IF(Q12=2,"ISZ "&AJ12,"DSZ "&AJ12))) -> JMP EGGS | AI12: =TEXT(Q12,"0")&","&AG12&AB12 -> 0,EGGS | AJ12: =AG12&AB12 -> EGGS | AK12: =AL12&AN12&AM12&AO12&" "&TEXT(U12,"0")&","&TEXT(V12,"0")&AP12 -> COMO 0,0,SEZ | AL12: =IF(W12=0,"COM",IF(W12=1,"NEG",IF(W12=2,"MOV",IF(W12=3,"INC",IF(W12=4,"ADC",IF(W12=5,"SUB",IF(W12=6,"ADD","AND"))))))) -> COM | AM12: =IF(X12=0,"",IF(X12=1,"L",IF(X12=2,"R","S"))) | AN12: =IF(Y12=0,"",IF(Y12=1,"Z",IF(Y12=2,"O","C"))) -> O | AO12: =IF(Z12=1,"#","") | AP12: =IF(AA12=0,"",IF(AA12=1,",SKP",IF(AA12=2,",SZC",IF(AA12=3,",SNC",IF(AA12=4,",SZR",IF(AA12=5,",SNR",IF(AA12=6,",SEZ",",SBN"))))))) -> ,SEZ | AQ12: =_xlfn.XLOOKUP(D12,Sheet2!$E$3:$E$101,Sheet2!$F$3:$F$101,"******************") -> ****************** | AR12: =IF(AY12=0,"NIO"&AV12&" "&AX12,IF(AY12=7,AZ12&" "&AX12,AS12&" "&TEXT(AT12,"0")&","&AX12)) -> NIO ** | AS12: =IF(AY12=1,"DIA"&AV12,IF(AY12=2,"DOA"&AV12,IF(AY12=3,"DIB"&AV12,IF(AY12=4,"DOB"&AV12,IF(AY12=5,"DIC"&AV12,"DOC"&AV12))))) -> DOC | AT12: =V12 -> 0 | AU12: =X12 -> 0 | AV12: =IF(AU12=0,"",IF(AU12=1,"S",IF(AU12=2,"C","P"))) | AW12: =M12*10+N12 -> 46 | AX12: =_xlfn.XLOOKUP(AW12,Sheet2!$Q$3:$Q$66,Sheet2!$R$3:$R$66,"**") -> ** | AY12: =W12 -> 0 | AZ12: =IF(AU12=0,"SKPBN",IF(AU12=1,"SKPBZ",IF(AU12=2,"SKPDN","SKPDZ"))) -> SKPBN
B13: =B12+1 -> 16 | C13: =IF(MOD(C12,10)=7,C12+3,C12+1) -> 46 | D13: 0 | E13: =_xlfn.XLOOKUP(C13,Sheet2!$N$3:$N$1000,Sheet2!$O$3:$O$1000,"") | G13: =DEC2OCT((2*(OCT2DEC(I13*100)+OCT2DEC(J13*10)+K13))+INT(L13/4)) -> 0 | H13: =(MOD(L13,4)*100)+(M13*10)+N13 -> 0 | I13: =MOD(INT(D13/100000),10) -> 0 | J13: =MOD(INT(D13/10000),10) -> 0 | K13: =MOD(INT(D13/1000),10) -> 0 | L13: =MOD(INT(D13/100),10) -> 0 | M13: =MOD(INT(D13/10),10) -> 0 | N13: =MOD(D13,10) -> 0 | O13: =INT(K13/4)+(J13*2)+(I13*16) -> 0 | P13: =(I13*4)+INT(J13/2) -> 0 | Q13: =V13 -> 0 | R13: =(MOD(L13,4)*100)+(M13*10)+N13 -> 0 | S13: =(MOD(K13,2)*2)+INT(L13/4) -> 0 | T13: =MOD(INT(K13/2),2) -> 0 | U13: =INT(J13/2) -> 0 | V13: =(MOD(J13,2)*2)+INT(K13/4) -> 0 | W13: =(MOD(K13,4)*2)+INT(L13/4) -> 0 | X13: =MOD(L13,4) -> 0 | Y13: =INT(M13/2) -> 0 | Z13: =MOD(M13,2) -> 0 | AA13: =N13 -> 0 | AB13: =IF(S13=0,AC13,IF(S13=1,IF(AD13="********",AF13,AD13),AF13&","&TEXT(S13,"0"))) -> 0 | AC13: =_xlfn.XLOOKUP(R13,Sheet2!$H$3:$H$258,Sheet2!$I$3:$I$258,"-----") -> 0 | AD13: =_xlfn.XLOOKUP(VALUE(AE13),Sheet2!$N$3:$N$1000,Sheet2!$O$3:$O$1000,"********") -> ******** | AE13: =IF(VALUE(AF13)<0,DEC2OCT(OCT2DEC(VALUE(C13))-OCT2DEC(-VALUE(AF13))),DEC2OCT(OCT2DEC(VALUE(C13))+OCT2DEC(VALUE(AF13)))) -> 46 | AF13: =IF(R13<200,"+"&TEXT(R13,"0"),"-"&TEXT(_xlfn.XLOOKUP(R13,Sheet2!$K$3:$K$130,Sheet2!$L$3:$L$130,"-----"),"0")) -> +0 | AG13: =IF(T13=1,"@","") | AH13: =IF(Q13=0,"JMP "&AJ13, IF(Q13=1,"JSR "&AJ13,IF(Q13=2,"ISZ "&AJ13,"DSZ "&AJ13))) -> JMP 0 | AI13: =TEXT(Q13,"0")&","&AG13&AB13 -> 0,0 | AJ13: =AG13&AB13 -> 0 | AK13: =AL13&AN13&AM13&AO13&" "&TEXT(U13,"0")&","&TEXT(V13,"0")&AP13 -> COM 0,0 | AL13: =IF(W13=0,"COM",IF(W13=1,"NEG",IF(W13=2,"MOV",IF(W13=3,"INC",IF(W13=4,"ADC",IF(W13=5,"SUB",IF(W13=6,"ADD","AND"))))))) -> COM | AM13: =IF(X13=0,"",IF(X13=1,"L",IF(X13=2,"R","S"))) | AN13: =IF(Y13=0,"",IF(Y13=1,"Z",IF(Y13=2,"O","C"))) | AO13: =IF(Z13=1,"#","") | AP13: =IF(AA13=0,"",IF(AA13=1,",SKP",IF(AA13=2,",SZC",IF(AA13=3,",SNC",IF(AA13=4,",SZR",IF(AA13=5,",SNR",IF(AA13=6,",SEZ",",SBN"))))))) | AQ13: =_xlfn.XLOOKUP(D13,Sheet2!$E$3:$E$101,Sheet2!$F$3:$F$101,"******************") -> 0 | AR13: =IF(AY13=0,"NIO"&AV13&" "&AX13,IF(AY13=7,AZ13&" "&AX13,AS13&" "&TEXT(AT13,"0")&","&AX13)) -> NIO 0 | AS13: =IF(AY13=1,"DIA"&AV13,IF(AY13=2,"DOA"&AV13,IF(AY13=3,"DIB"&AV13,IF(AY13=4,"DOB"&AV13,IF(AY13=5,"DIC"&AV13,"DOC"&AV13))))) -> DOC | AT13: =V13 -> 0 | AU13: =X13 -> 0 | AV13: =IF(AU13=0,"",IF(AU13=1,"S",IF(AU13=2,"C","P"))) | AW13: =M13*10+N13 -> 0 | AX13: =_xlfn.XLOOKUP(AW13,Sheet2!$Q$3:$Q$66,Sheet2!$R$3:$R$66,"**") -> 0 | AY13: =W13 -> 0 | AZ13: =IF(AU13=0,"SKPBN",IF(AU13=1,"SKPBZ",IF(AU13=2,"SKPDN","SKPDZ"))) -> SKPBN
B14: =B13+1 -> 17 | C14: =IF(MOD(C13,10)=7,C13+3,C13+1) -> 47 | D14: 0 | E14: =_xlfn.XLOOKUP(C14,Sheet2!$N$3:$N$1000,Sheet2!$O$3:$O$1000,"") | G14: =DEC2OCT((2*(OCT2DEC(I14*100)+OCT2DEC(J14*10)+K14))+INT(L14/4)) -> 0 | H14: =(MOD(L14,4)*100)+(M14*10)+N14 -> 0 | I14: =MOD(INT(D14/100000),10) -> 0 | J14: =MOD(INT(D14/10000),10) -> 0 | K14: =MOD(INT(D14/1000),10) -> 0 | L14: =MOD(INT(D14/100),10) -> 0 | M14: =MOD(INT(D14/10),10) -> 0 | N14: =MOD(D14,10) -> 0 | O14: =INT(K14/4)+(J14*2)+(I14*16) -> 0 | P14: =(I14*4)+INT(J14/2) -> 0 | Q14: =V14 -> 0 | R14: =(MOD(L14,4)*100)+(M14*10)+N14 -> 0 | S14: =(MOD(K14,2)*2)+INT(L14/4) -> 0 | T14: =MOD(INT(K14/2),2) -> 0 | U14: =INT(J14/2) -> 0 | V14: =(MOD(J14,2)*2)+INT(K14/4) -> 0 | W14: =(MOD(K14,4)*2)+INT(L14/4) -> 0 | X14: =MOD(L14,4) -> 0 | Y14: =INT(M14/2) -> 0 | Z14: =MOD(M14,2) -> 0 | AA14: =N14 -> 0 | AB14: =IF(S14=0,AC14,IF(S14=1,IF(AD14="********",AF14,AD14),AF14&","&TEXT(S14,"0"))) -> 0 | AC14: =_xlfn.XLOOKUP(R14,Sheet2!$H$3:$H$258,Sheet2!$I$3:$I$258,"-----") -> 0 | AD14: =_xlfn.XLOOKUP(VALUE(AE14),Sheet2!$N$3:$N$1000,Sheet2!$O$3:$O$1000,"********") -> ******** | AE14: =IF(VALUE(AF14)<0,DEC2OCT(OCT2DEC(VALUE(C14))-OCT2DEC(-VALUE(AF14))),DEC2OCT(OCT2DEC(VALUE(C14))+OCT2DEC(VALUE(AF14)))) -> 47 | AF14: =IF(R14<200,"+"&TEXT(R14,"0"),"-"&TEXT(_xlfn.XLOOKUP(R14,Sheet2!$K$3:$K$130,Sheet2!$L$3:$L$130,"-----"),"0")) -> +0 | AG14: =IF(T14=1,"@","") | AH14: =IF(Q14=0,"JMP "&AJ14, IF(Q14=1,"JSR "&AJ14,IF(Q14=2,"ISZ "&AJ14,"DSZ "&AJ14))) -> JMP 0 | AI14: =TEXT(Q14,"0")&","&AG14&AB14 -> 0,0 | AJ14: =AG14&AB14 -> 0 | AK14: =AL14&AN14&AM14&AO14&" "&TEXT(U14,"0")&","&TEXT(V14,"0")&AP14 -> COM 0,0 | AL14: =IF(W14=0,"COM",IF(W14=1,"NEG",IF(W14=2,"MOV",IF(W14=3,"INC",IF(W14=4,"ADC",IF(W14=5,"SUB",IF(W14=6,"ADD","AND"))))))) -> COM | AM14: =IF(X14=0,"",IF(X14=1,"L",IF(X14=2,"R","S"))) | AN14: =IF(Y14=0,"",IF(Y14=1,"Z",IF(Y14=2,"O","C"))) | AO14: =IF(Z14=1,"#","") | AP14: =IF(AA14=0,"",IF(AA14=1,",SKP",IF(AA14=2,",SZC",IF(AA14=3,",SNC",IF(AA14=4,",SZR",IF(AA14=5,",SNR",IF(AA14=6,",SEZ",",SBN"))))))) | AQ14: =_xlfn.XLOOKUP(D14,Sheet2!$E$3:$E$101,Sheet2!$F$3:$F$101,"******************") -> 0 | AR14: =IF(AY14=0,"NIO"&AV14&" "&AX14,IF(AY14=7,AZ14&" "&AX14,AS14&" "&TEXT(AT14,"0")&","&AX14)) -> NIO 0 | AS14: =IF(AY14=1,"DIA"&AV14,IF(AY14=2,"DOA"&AV14,IF(AY14=3,"DIB"&AV14,IF(AY14=4,"DOB"&AV14,IF(AY14=5,"DIC"&AV14,"DOC"&AV14))))) -> DOC | AT14: =V14 -> 0 | AU14: =X14 -> 0 | AV14: =IF(AU14=0,"",IF(AU14=1,"S",IF(AU14=2,"C","P"))) | AW14: =M14*10+N14 -> 0 | AX14: =_xlfn.XLOOKUP(AW14,Sheet2!$Q$3:$Q$66,Sheet2!$R$3:$R$66,"**") -> 0 | AY14: =W14 -> 0 | AZ14: =IF(AU14=0,"SKPBN",IF(AU14=1,"SKPBZ",IF(AU14=2,"SKPDN","SKPDZ"))) -> SKPBN
B15: =B14+1 -> 18 | C15: =IF(MOD(C14,10)=7,C14+3,C14+1) -> 50 | D15: 0 | E15: =_xlfn.XLOOKUP(C15,Sheet2!$N$3:$N$1000,Sheet2!$O$3:$O$1000,"") | G15: =DEC2OCT((2*(OCT2DEC(I15*100)+OCT2DEC(J15*10)+K15))+INT(L15/4)) -> 0 | H15: =(MOD(L15,4)*100)+(M15*10)+N15 -> 0 | I15: =MOD(INT(D15/100000),10) -> 0 | J15: =MOD(INT(D15/10000),10) -> 0 | K15: =MOD(INT(D15/1000),10) -> 0 | L15: =MOD(INT(D15/100),10) -> 0 | M15: =MOD(INT(D15/10),10) -> 0 | N15: =MOD(D15,10) -> 0 | O15: =INT(K15/4)+(J15*2)+(I15*16) -> 0 | P15: =(I15*4)+INT(J15/2) -> 0 | Q15: =V15 -> 0 | R15: =(MOD(L15,4)*100)+(M15*10)+N15 -> 0 | S15: =(MOD(K15,2)*2)+INT(L15/4) -> 0 | T15: =MOD(INT(K15/2),2) -> 0 | U15: =INT(J15/2) -> 0 | V15: =(MOD(J15,2)*2)+INT(K15/4) -> 0 | W15: =(MOD(K15,4)*2)+INT(L15/4) -> 0 | X15: =MOD(L15,4) -> 0 | Y15: =INT(M15/2) -> 0 | Z15: =MOD(M15,2) -> 0 | AA15: =N15 -> 0 | AB15: =IF(S15=0,AC15,IF(S15=1,IF(AD15="********",AF15,AD15),AF15&","&TEXT(S15,"0"))) -> 0 | AC15: =_xlfn.XLOOKUP(R15,Sheet2!$H$3:$H$258,Sheet2!$I$3:$I$258,"-----") -> 0 | AD15: =_xlfn.XLOOKUP(VALUE(AE15),Sheet2!$N$3:$N$1000,Sheet2!$O$3:$O$1000,"********") -> ******** | AE15: =IF(VALUE(AF15)<0,DEC2OCT(OCT2DEC(VALUE(C15))-OCT2DEC(-VALUE(AF15))),DEC2OCT(OCT2DEC(VALUE(C15))+OCT2DEC(VALUE(AF15)))) -> 50 | AF15: =IF(R15<200,"+"&TEXT(R15,"0"),"-"&TEXT(_xlfn.XLOOKUP(R15,Sheet2!$K$3:$K$130,Sheet2!$L$3:$L$130,"-----"),"0")) -> +0 | AG15: =IF(T15=1,"@","") | AH15: =IF(Q15=0,"JMP "&AJ15, IF(Q15=1,"JSR "&AJ15,IF(Q15=2,"ISZ "&AJ15,"DSZ "&AJ15))) -> JMP 0 | AI15: =TEXT(Q15,"0")&","&AG15&AB15 -> 0,0 | AJ15: =AG15&AB15 -> 0 | AK15: =AL15&AN15&AM15&AO15&" "&TEXT(U15,"0")&","&TEXT(V15,"0")&AP15 -> COM 0,0 | AL15: =IF(W15=0,"COM",IF(W15=1,"NEG",IF(W15=2,"MOV",IF(W15=3,"INC",IF(W15=4,"ADC",IF(W15=5,"SUB",IF(W15=6,"ADD","AND"))))))) -> COM | AM15: =IF(X15=0,"",IF(X15=1,"L",IF(X15=2,"R","S"))) | AN15: =IF(Y15=0,"",IF(Y15=1,"Z",IF(Y15=2,"O","C"))) | AO15: =IF(Z15=1,"#","") | AP15: =IF(AA15=0,"",IF(AA15=1,",SKP",IF(AA15=2,",SZC",IF(AA15=3,",SNC",IF(AA15=4,",SZR",IF(AA15=5,",SNR",IF(AA15=6,",SEZ",",SBN"))))))) | AQ15: =_xlfn.XLOOKUP(D15,Sheet2!$E$3:$E$101,Sheet2!$F$3:$F$101,"******************") -> 0 | AR15: =IF(AY15=0,"NIO"&AV15&" "&AX15,IF(AY15=7,AZ15&" "&AX15,AS15&" "&TEXT(AT15,"0")&","&AX15)) -> NIO 0 | AS15: =IF(AY15=1,"DIA"&AV15,IF(AY15=2,"DOA"&AV15,IF(AY15=3,"DIB"&AV15,IF(AY15=4,"DOB"&AV15,IF(AY15=5,"DIC"&AV15,"DOC"&AV15))))) -> DOC | AT15: =V15 -> 0 | AU15: =X15 -> 0 | AV15: =IF(AU15=0,"",IF(AU15=1,"S",IF(AU15=2,"C","P"))) | AW15: =M15*10+N15 -> 0 | AX15: =_xlfn.XLOOKUP(AW15,Sheet2!$Q$3:$Q$66,Sheet2!$R$3:$R$66,"**") -> 0 | AY15: =W15 -> 0 | AZ15: =IF(AU15=0,"SKPBN",IF(AU15=1,"SKPBZ",IF(AU15=2,"SKPDN","SKPDZ"))) -> SKPBN
B16: =B15+1 -> 19 | C16: =IF(MOD(C15,10)=7,C15+3,C15+1) -> 51 | D16: 0 | E16: =_xlfn.XLOOKUP(C16,Sheet2!$N$3:$N$1000,Sheet2!$O$3:$O$1000,"") | G16: =DEC2OCT((2*(OCT2DEC(I16*100)+OCT2DEC(J16*10)+K16))+INT(L16/4)) -> 0 | H16: =(MOD(L16,4)*100)+(M16*10)+N16 -> 0 | I16: =MOD(INT(D16/100000),10) -> 0 | J16: =MOD(INT(D16/10000),10) -> 0 | K16: =MOD(INT(D16/1000),10) -> 0 | L16: =MOD(INT(D16/100),10) -> 0 | M16: =MOD(INT(D16/10),10) -> 0 | N16: =MOD(D16,10) -> 0 | O16: =INT(K16/4)+(J16*2)+(I16*16) -> 0 | P16: =(I16*4)+INT(J16/2) -> 0 | Q16: =V16 -> 0 | R16: =(MOD(L16,4)*100)+(M16*10)+N16 -> 0 | S16: =(MOD(K16,2)*2)+INT(L16/4) -> 0 | T16: =MOD(INT(K16/2),2) -> 0 | U16: =INT(J16/2) -> 0 | V16: =(MOD(J16,2)*2)+INT(K16/4) -> 0 | W16: =(MOD(K16,4)*2)+INT(L16/4) -> 0 | X16: =MOD(L16,4) -> 0 | Y16: =INT(M16/2) -> 0 | Z16: =MOD(M16,2) -> 0 | AA16: =N16 -> 0 | AB16: =IF(S16=0,AC16,IF(S16=1,IF(AD16="********",AF16,AD16),AF16&","&TEXT(S16,"0"))) -> 0 | AC16: =_xlfn.XLOOKUP(R16,Sheet2!$H$3:$H$258,Sheet2!$I$3:$I$258,"-----") -> 0 | AD16: =_xlfn.XLOOKUP(VALUE(AE16),Sheet2!$N$3:$N$1000,Sheet2!$O$3:$O$1000,"********") -> ******** | AE16: =IF(VALUE(AF16)<0,DEC2OCT(OCT2DEC(VALUE(C16))-OCT2DEC(-VALUE(AF16))),DEC2OCT(OCT2DEC(VALUE(C16))+OCT2DEC(VALUE(AF16)))) -> 51 | AF16: =IF(R16<200,"+"&TEXT(R16,"0"),"-"&TEXT(_xlfn.XLOOKUP(R16,Sheet2!$K$3:$K$130,Sheet2!$L$3:$L$130,"-----"),"0")) -> +0 | AG16: =IF(T16=1,"@","") | AH16: =IF(Q16=0,"JMP "&AJ16, IF(Q16=1,"JSR "&AJ16,IF(Q16=2,"ISZ "&AJ16,"DSZ "&AJ16))) -> JMP 0 | AI16: =TEXT(Q16,"0")&","&AG16&AB16 -> 0,0 | AJ16: =AG16&AB16 -> 0 | AK16: =AL16&AN16&AM16&AO16&" "&TEXT(U16,"0")&","&TEXT(V16,"0")&AP16 -> COM 0,0 | AL16: =IF(W16=0,"COM",IF(W16=1,"NEG",IF(W16=2,"MOV",IF(W16=3,"INC",IF(W16=4,"ADC",IF(W16=5,"SUB",IF(W16=6,"ADD","AND"))))))) -> COM | AM16: =IF(X16=0,"",IF(X16=1,"L",IF(X16=2,"R","S"))) | AN16: =IF(Y16=0,"",IF(Y16=1,"Z",IF(Y16=2,"O","C"))) | AO16: =IF(Z16=1,"#","") | AP16: =IF(AA16=0,"",IF(AA16=1,",SKP",IF(AA16=2,",SZC",IF(AA16=3,",SNC",IF(AA16=4,",SZR",IF(AA16=5,",SNR",IF(AA16=6,",SEZ",",SBN"))))))) | AQ16: =_xlfn.XLOOKUP(D16,Sheet2!$E$3:$E$101,Sheet2!$F$3:$F$101,"******************") -> 0 | AR16: =IF(AY16=0,"NIO"&AV16&" "&AX16,IF(AY16=7,AZ16&" "&AX16,AS16&" "&TEXT(AT16,"0")&","&AX16)) -> NIO 0 | AS16: =IF(AY16=1,"DIA"&AV16,IF(AY16=2,"DOA"&AV16,IF(AY16=3,"DIB"&AV16,IF(AY16=4,"DOB"&AV16,IF(AY16=5,"DIC"&AV16,"DOC"&AV16))))) -> DOC | AT16: =V16 -> 0 | AU16: =X16 -> 0 | AV16: =IF(AU16=0,"",IF(AU16=1,"S",IF(AU16=2,"C","P"))) | AW16: =M16*10+N16 -> 0 | AX16: =_xlfn.XLOOKUP(AW16,Sheet2!$Q$3:$Q$66,Sheet2!$R$3:$R$66,"**") -> 0 | AY16: =W16 -> 0 | AZ16: =IF(AU16=0,"SKPBN",IF(AU16=1,"SKPBZ",IF(AU16=2,"SKPDN","SKPDZ"))) -> SKPBN
B17: =B16+1 -> 20 | C17: =IF(MOD(C16,10)=7,C16+3,C16+1) -> 52 | D17: 0 | E17: =_xlfn.XLOOKUP(C17,Sheet2!$N$3:$N$1000,Sheet2!$O$3:$O$1000,"") | G17: =DEC2OCT((2*(OCT2DEC(I17*100)+OCT2DEC(J17*10)+K17))+INT(L17/4)) -> 0 | H17: =(MOD(L17,4)*100)+(M17*10)+N17 -> 0 | I17: =MOD(INT(D17/100000),10) -> 0 | J17: =MOD(INT(D17/10000),10) -> 0 | K17: =MOD(INT(D17/1000),10) -> 0 | L17: =MOD(INT(D17/100),10) -> 0 | M17: =MOD(INT(D17/10),10) -> 0 | N17: =MOD(D17,10) -> 0 | O17: =INT(K17/4)+(J17*2)+(I17*16) -> 0 | P17: =(I17*4)+INT(J17/2) -> 0 | Q17: =V17 -> 0 | R17: =(MOD(L17,4)*100)+(M17*10)+N17 -> 0 | S17: =(MOD(K17,2)*2)+INT(L17/4) -> 0 | T17: =MOD(INT(K17/2),2) -> 0 | U17: =INT(J17/2) -> 0 | V17: =(MOD(J17,2)*2)+INT(K17/4) -> 0 | W17: =(MOD(K17,4)*2)+INT(L17/4) -> 0 | X17: =MOD(L17,4) -> 0 | Y17: =INT(M17/2) -> 0 | Z17: =MOD(M17,2) -> 0 | AA17: =N17 -> 0 | AB17: =IF(S17=0,AC17,IF(S17=1,IF(AD17="********",AF17,AD17),AF17&","&TEXT(S17,"0"))) -> 0 | AC17: =_xlfn.XLOOKUP(R17,Sheet2!$H$3:$H$258,Sheet2!$I$3:$I$258,"-----") -> 0 | AD17: =_xlfn.XLOOKUP(VALUE(AE17),Sheet2!$N$3:$N$1000,Sheet2!$O$3:$O$1000,"********") -> ******** | AE17: =IF(VALUE(AF17)<0,DEC2OCT(OCT2DEC(VALUE(C17))-OCT2DEC(-VALUE(AF17))),DEC2OCT(OCT2DEC(VALUE(C17))+OCT2DEC(VALUE(AF17)))) -> 52 | AF17: =IF(R17<200,"+"&TEXT(R17,"0"),"-"&TEXT(_xlfn.XLOOKUP(R17,Sheet2!$K$3:$K$130,Sheet2!$L$3:$L$130,"-----"),"0")) -> +0 | AG17: =IF(T17=1,"@","") | AH17: =IF(Q17=0,"JMP "&AJ17, IF(Q17=1,"JSR "&AJ17,IF(Q17=2,"ISZ "&AJ17,"DSZ "&AJ17))) -> JMP 0 | AI17: =TEXT(Q17,"0")&","&AG17&AB17 -> 0,0 | AJ17: =AG17&AB17 -> 0 | AK17: =AL17&AN17&AM17&AO17&" "&TEXT(U17,"0")&","&TEXT(V17,"0")&AP17 -> COM 0,0 | AL17: =IF(W17=0,"COM",IF(W17=1,"NEG",IF(W17=2,"MOV",IF(W17=3,"INC",IF(W17=4,"ADC",IF(W17=5,"SUB",IF(W17=6,"ADD","AND"))))))) -> COM | AM17: =IF(X17=0,"",IF(X17=1,"L",IF(X17=2,"R","S"))) | AN17: =IF(Y17=0,"",IF(Y17=1,"Z",IF(Y17=2,"O","C"))) | AO17: =IF(Z17=1,"#","") | AP17: =IF(AA17=0,"",IF(AA17=1,",SKP",IF(AA17=2,",SZC",IF(AA17=3,",SNC",IF(AA17=4,",SZR",IF(AA17=5,",SNR",IF(AA17=6,",SEZ",",SBN"))))))) | AQ17: =_xlfn.XLOOKUP(D17,Sheet2!$E$3:$E$101,Sheet2!$F$3:$F$101,"******************") -> 0 | AR17: =IF(AY17=0,"NIO"&AV17&" "&AX17,IF(AY17=7,AZ17&" "&AX17,AS17&" "&TEXT(AT17,"0")&","&AX17)) -> NIO 0 | AS17: =IF(AY17=1,"DIA"&AV17,IF(AY17=2,"DOA"&AV17,IF(AY17=3,"DIB"&AV17,IF(AY17=4,"DOB"&AV17,IF(AY17=5,"DIC"&AV17,"DOC"&AV17))))) -> DOC | AT17: =V17 -> 0 | AU17: =X17 -> 0 | AV17: =IF(AU17=0,"",IF(AU17=1,"S",IF(AU17=2,"C","P"))) | AW17: =M17*10+N17 -> 0 | AX17: =_xlfn.XLOOKUP(AW17,Sheet2!$Q$3:$Q$66,Sheet2!$R$3:$R$66,"**") -> 0 | AY17: =W17 -> 0 | AZ17: =IF(AU17=0,"SKPBN",IF(AU17=1,"SKPBZ",IF(AU17=2,"SKPDN","SKPDZ"))) -> SKPBN
B18: 22 | C18: =IF(MOD(C17,10)=7,C17+3,C17+1) -> 53 | D18: 0 | E18: =_xlfn.XLOOKUP(C18,Sheet2!$N$3:$N$1000,Sheet2!$O$3:$O$1000,"") | G18: =DEC2OCT((2*(OCT2DEC(I18*100)+OCT2DEC(J18*10)+K18))+INT(L18/4)) -> 0 | H18: =(MOD(L18,4)*100)+(M18*10)+N18 -> 0 | I18: =MOD(INT(D18/100000),10) -> 0 | J18: =MOD(INT(D18/10000),10) -> 0 | K18: =MOD(INT(D18/1000),10) -> 0 | L18: =MOD(INT(D18/100),10) -> 0 | M18: =MOD(INT(D18/10),10) -> 0 | N18: =MOD(D18,10) -> 0 | O18: =INT(K18/4)+(J18*2)+(I18*16) -> 0 | P18: =(I18*4)+INT(J18/2) -> 0 | Q18: =V18 -> 0 | R18: =(MOD(L18,4)*100)+(M18*10)+N18 -> 0 | S18: =(MOD(K18,2)*2)+INT(L18/4) -> 0 | T18: =MOD(INT(K18/2),2) -> 0 | U18: =INT(J18/2) -> 0 | V18: =(MOD(J18,2)*2)+INT(K18/4) -> 0 | W18: =(MOD(K18,4)*2)+INT(L18/4) -> 0 | X18: =MOD(L18,4) -> 0 | Y18: =INT(M18/2) -> 0 | Z18: =MOD(M18,2) -> 0 | AA18: =N18 -> 0 | AB18: =IF(S18=0,AC18,IF(S18=1,IF(AD18="********",AF18,AD18),AF18&","&TEXT(S18,"0"))) -> 0 | AC18: =_xlfn.XLOOKUP(R18,Sheet2!$H$3:$H$258,Sheet2!$I$3:$I$258,"-----") -> 0 | AD18: =_xlfn.XLOOKUP(VALUE(AE18),Sheet2!$N$3:$N$1000,Sheet2!$O$3:$O$1000,"********") -> ******** | AE18: =IF(VALUE(AF18)<0,DEC2OCT(OCT2DEC(VALUE(C18))-OCT2DEC(-VALUE(AF18))),DEC2OCT(OCT2DEC(VALUE(C18))+OCT2DEC(VALUE(AF18)))) -> 53 | AF18: =IF(R18<200,"+"&TEXT(R18,"0"),"-"&TEXT(_xlfn.XLOOKUP(R18,Sheet2!$K$3:$K$130,Sheet2!$L$3:$L$130,"-----"),"0")) -> +0 | AG18: =IF(T18=1,"@","") | AH18: =IF(Q18=0,"JMP "&AJ18, IF(Q18=1,"JSR "&AJ18,IF(Q18=2,"ISZ "&AJ18,"DSZ "&AJ18))) -> JMP 0 | AI18: =TEXT(Q18,"0")&","&AG18&AB18 -> 0,0 | AJ18: =AG18&AB18 -> 0 | AK18: =AL18&AN18&AM18&AO18&" "&TEXT(U18,"0")&","&TEXT(V18,"0")&AP18 -> COM 0,0 | AL18: =IF(W18=0,"COM",IF(W18=1,"NEG",IF(W18=2,"MOV",IF(W18=3,"INC",IF(W18=4,"ADC",IF(W18=5,"SUB",IF(W18=6,"ADD","AND"))))))) -> COM | AM18: =IF(X18=0,"",IF(X18=1,"L",IF(X18=2,"R","S"))) | AN18: =IF(Y18=0,"",IF(Y18=1,"Z",IF(Y18=2,"O","C"))) | AO18: =IF(Z18=1,"#","") | AP18: =IF(AA18=0,"",IF(AA18=1,",SKP",IF(AA18=2,",SZC",IF(AA18=3,",SNC",IF(AA18=4,",SZR",IF(AA18=5,",SNR",IF(AA18=6,",SEZ",",SBN"))))))) | AQ18: =_xlfn.XLOOKUP(D18,Sheet2!$E$3:$E$101,Sheet2!$F$3:$F$101,"******************") -> 0 | AR18: =IF(AY18=0,"NIO"&AV18&" "&AX18,IF(AY18=7,AZ18&" "&AX18,AS18&" "&TEXT(AT18,"0")&","&AX18)) -> NIO 0 | AS18: =IF(AY18=1,"DIA"&AV18,IF(AY18=2,"DOA"&AV18,IF(AY18=3,"DIB"&AV18,IF(AY18=4,"DOB"&AV18,IF(AY18=5,"DIC"&AV18,"DOC"&AV18))))) -> DOC | AT18: =V18 -> 0 | AU18: =X18 -> 0 | AV18: =IF(AU18=0,"",IF(AU18=1,"S",IF(AU18=2,"C","P"))) | AW18: =M18*10+N18 -> 0 | AX18: =_xlfn.XLOOKUP(AW18,Sheet2!$Q$3:$Q$66,Sheet2!$R$3:$R$66,"**") -> 0 | AY18: =W18 -> 0 | AZ18: =IF(AU18=0,"SKPBN",IF(AU18=1,"SKPBZ",IF(AU18=2,"SKPDN","SKPDZ"))) -> SKPBN
B19: =B18+1 -> 23 | C19: =IF(MOD(C18,10)=7,C18+3,C18+1) -> 54 | D19: 40000 | E19: =_xlfn.XLOOKUP(C19,Sheet2!$N$3:$N$1000,Sheet2!$O$3:$O$1000,"") | G19: =DEC2OCT((2*(OCT2DEC(I19*100)+OCT2DEC(J19*10)+K19))+INT(L19/4)) -> 100 | H19: =(MOD(L19,4)*100)+(M19*10)+N19 -> 0 | I19: =MOD(INT(D19/100000),10) -> 0 | J19: =MOD(INT(D19/10000),10) -> 4 | K19: =MOD(INT(D19/1000),10) -> 0 | L19: =MOD(INT(D19/100),10) -> 0 | M19: =MOD(INT(D19/10),10) -> 0 | N19: =MOD(D19,10) -> 0 | O19: =INT(K19/4)+(J19*2)+(I19*16) -> 8 | P19: =(I19*4)+INT(J19/2) -> 2 | Q19: =V19 -> 0 | R19: =(MOD(L19,4)*100)+(M19*10)+N19 -> 0 | S19: =(MOD(K19,2)*2)+INT(L19/4) -> 0 | T19: =MOD(INT(K19/2),2) -> 0 | U19: =INT(J19/2) -> 2 | V19: =(MOD(J19,2)*2)+INT(K19/4) -> 0 | W19: =(MOD(K19,4)*2)+INT(L19/4) -> 0 | X19: =MOD(L19,4) -> 0 | Y19: =INT(M19/2) -> 0 | Z19: =MOD(M19,2) -> 0 | AA19: =N19 -> 0 | AB19: =IF(S19=0,AC19,IF(S19=1,IF(AD19="********",AF19,AD19),AF19&","&TEXT(S19,"0"))) -> 0 | AC19: =_xlfn.XLOOKUP(R19,Sheet2!$H$3:$H$258,Sheet2!$I$3:$I$258,"-----") -> 0 | AD19: =_xlfn.XLOOKUP(VALUE(AE19),Sheet2!$N$3:$N$1000,Sheet2!$O$3:$O$1000,"********") -> ******** | AE19: =IF(VALUE(AF19)<0,DEC2OCT(OCT2DEC(VALUE(C19))-OCT2DEC(-VALUE(AF19))),DEC2OCT(OCT2DEC(VALUE(C19))+OCT2DEC(VALUE(AF19)))) -> 54 | AF19: =IF(R19<200,"+"&TEXT(R19,"0"),"-"&TEXT(_xlfn.XLOOKUP(R19,Sheet2!$K$3:$K$130,Sheet2!$L$3:$L$130,"-----"),"0")) -> +0 | AG19: =IF(T19=1,"@","") | AH19: =IF(Q19=0,"JMP "&AJ19, IF(Q19=1,"JSR "&AJ19,IF(Q19=2,"ISZ "&AJ19,"DSZ "&AJ19))) -> JMP 0 | AI19: =TEXT(Q19,"0")&","&AG19&AB19 -> 0,0 | AJ19: =AG19&AB19 -> 0 | AK19: =AL19&AN19&AM19&AO19&" "&TEXT(U19,"0")&","&TEXT(V19,"0")&AP19 -> COM 2,0 | AL19: =IF(W19=0,"COM",IF(W19=1,"NEG",IF(W19=2,"MOV",IF(W19=3,"INC",IF(W19=4,"ADC",IF(W19=5,"SUB",IF(W19=6,"ADD","AND"))))))) -> COM | AM19: =IF(X19=0,"",IF(X19=1,"L",IF(X19=2,"R","S"))) | AN19: =IF(Y19=0,"",IF(Y19=1,"Z",IF(Y19=2,"O","C"))) | AO19: =IF(Z19=1,"#","") | AP19: =IF(AA19=0,"",IF(AA19=1,",SKP",IF(AA19=2,",SZC",IF(AA19=3,",SNC",IF(AA19=4,",SZR",IF(AA19=5,",SNR",IF(AA19=6,",SEZ",",SBN"))))))) | AQ19: =_xlfn.XLOOKUP(D19,Sheet2!$E$3:$E$101,Sheet2!$F$3:$F$101,"******************") -> ****************** | AR19: =IF(AY19=0,"NIO"&AV19&" "&AX19,IF(AY19=7,AZ19&" "&AX19,AS19&" "&TEXT(AT19,"0")&","&AX19)) -> NIO 0 | AS19: =IF(AY19=1,"DIA"&AV19,IF(AY19=2,"DOA"&AV19,IF(AY19=3,"DIB"&AV19,IF(AY19=4,"DOB"&AV19,IF(AY19=5,"DIC"&AV19,"DOC"&AV19))))) -> DOC | AT19: =V19 -> 0 | AU19: =X19 -> 0 | AV19: =IF(AU19=0,"",IF(AU19=1,"S",IF(AU19=2,"C","P"))) | AW19: =M19*10+N19 -> 0 | AX19: =_xlfn.XLOOKUP(AW19,Sheet2!$Q$3:$Q$66,Sheet2!$R$3:$R$66,"**") -> 0 | AY19: =W19 -> 0 | AZ19: =IF(AU19=0,"SKPBN",IF(AU19=1,"SKPBZ",IF(AU19=2,"SKPDN","SKPDZ"))) -> SKPBN
B20: =B19+1 -> 24 | C20: =IF(MOD(C19,10)=7,C19+3,C19+1) -> 55 | D20: 100000 | E20: =_xlfn.XLOOKUP(C20,Sheet2!$N$3:$N$1000,Sheet2!$O$3:$O$1000,"") | G20: =DEC2OCT((2*(OCT2DEC(I20*100)+OCT2DEC(J20*10)+K20))+INT(L20/4)) -> 200 | H20: =(MOD(L20,4)*100)+(M20*10)+N20 -> 0 | I20: =MOD(INT(D20/100000),10) -> 1 | J20: =MOD(INT(D20/10000),10) -> 0 | K20: =MOD(INT(D20/1000),10) -> 0 | L20: =MOD(INT(D20/100),10) -> 0 | M20: =MOD(INT(D20/10),10) -> 0 | N20: =MOD(D20,10) -> 0 | O20: =INT(K20/4)+(J20*2)+(I20*16) -> 16 | P20: =(I20*4)+INT(J20/2) -> 4 | Q20: =V20 -> 0 | R20: =(MOD(L20,4)*100)+(M20*10)+N20 -> 0 | S20: =(MOD(K20,2)*2)+INT(L20/4) -> 0 | T20: =MOD(INT(K20/2),2) -> 0 | U20: =INT(J20/2) -> 0 | V20: =(MOD(J20,2)*2)+INT(K20/4) -> 0 | W20: =(MOD(K20,4)*2)+INT(L20/4) -> 0 | X20: =MOD(L20,4) -> 0 | Y20: =INT(M20/2) -> 0 | Z20: =MOD(M20,2) -> 0 | AA20: =N20 -> 0 | AB20: =IF(S20=0,AC20,IF(S20=1,IF(AD20="********",AF20,AD20),AF20&","&TEXT(S20,"0"))) -> 0 | AC20: =_xlfn.XLOOKUP(R20,Sheet2!$H$3:$H$258,Sheet2!$I$3:$I$258,"-----") -> 0 | AD20: =_xlfn.XLOOKUP(VALUE(AE20),Sheet2!$N$3:$N$1000,Sheet2!$O$3:$O$1000,"********") -> ******** | AE20: =IF(VALUE(AF20)<0,DEC2OCT(OCT2DEC(VALUE(C20))-OCT2DEC(-VALUE(AF20))),DEC2OCT(OCT2DEC(VALUE(C20))+OCT2DEC(VALUE(AF20)))) -> 55 | AF20: =IF(R20<200,"+"&TEXT(R20,"0"),"-"&TEXT(_xlfn.XLOOKUP(R20,Sheet2!$K$3:$K$130,Sheet2!$L$3:$L$130,"-----"),"0")) -> +0 | AG20: =IF(T20=1,"@","") | AH20: =IF(Q20=0,"JMP "&AJ20, IF(Q20=1,"JSR "&AJ20,IF(Q20=2,"ISZ "&AJ20,"DSZ "&AJ20))) -> JMP 0 | AI20: =TEXT(Q20,"0")&","&AG20&AB20 -> 0,0 | AJ20: =AG20&AB20 -> 0 | AK20: =AL20&AN20&AM20&AO20&" "&TEXT(U20,"0")&","&TEXT(V20,"0")&AP20 -> COM 0,0 | AL20: =IF(W20=0,"COM",IF(W20=1,"NEG",IF(W20=2,"MOV",IF(W20=3,"INC",IF(W20=4,"ADC",IF(W20=5,"SUB",IF(W20=6,"ADD","AND"))))))) -> COM | AM20: =IF(X20=0,"",IF(X20=1,"L",IF(X20=2,"R","S"))) | AN20: =IF(Y20=0,"",IF(Y20=1,"Z",IF(Y20=2,"O","C"))) | AO20: =IF(Z20=1,"#","") | AP20: =IF(AA20=0,"",IF(AA20=1,",SKP",IF(AA20=2,",SZC",IF(AA20=3,",SNC",IF(AA20=4,",SZR",IF(AA20=5,",SNR",IF(AA20=6,",SEZ",",SBN"))))))) | AQ20: =_xlfn.XLOOKUP(D20,Sheet2!$E$3:$E$101,Sheet2!$F$3:$F$101,"******************") -> ****************** | AR20: =IF(AY20=0,"NIO"&AV20&" "&AX20,IF(AY20=7,AZ20&" "&AX20,AS20&" "&TEXT(AT20,"0")&","&AX20)) -> NIO 0 | AS20: =IF(AY20=1,"DIA"&AV20,IF(AY20=2,"DOA"&AV20,IF(AY20=3,"DIB"&AV20,IF(AY20=4,"DOB"&AV20,IF(AY20=5,"DIC"&AV20,"DOC"&AV20))))) -> DOC | AT20: =V20 -> 0 | AU20: =X20 -> 0 | AV20: =IF(AU20=0,"",IF(AU20=1,"S",IF(AU20=2,"C","P"))) | AW20: =M20*10+N20 -> 0 | AX20: =_xlfn.XLOOKUP(AW20,Sheet2!$Q$3:$Q$66,Sheet2!$R$3:$R$66,"**") -> 0 | AY20: =W20 -> 0 | AZ20: =IF(AU20=0,"SKPBN",IF(AU20=1,"SKPBZ",IF(AU20=2,"SKPDN","SKPDZ"))) -> SKPBN
B21: =B20+1 -> 25 | C21: =IF(MOD(C20,10)=7,C20+3,C20+1) -> 56 | D21: 140000 | E21: =_xlfn.XLOOKUP(C21,Sheet2!$N$3:$N$1000,Sheet2!$O$3:$O$1000,"") | G21: =DEC2OCT((2*(OCT2DEC(I21*100)+OCT2DEC(J21*10)+K21))+INT(L21/4)) -> 300 | H21: =(MOD(L21,4)*100)+(M21*10)+N21 -> 0 | I21: =MOD(INT(D21/100000),10) -> 1 | J21: =MOD(INT(D21/10000),10) -> 4 | K21: =MOD(INT(D21/1000),10) -> 0 | L21: =MOD(INT(D21/100),10) -> 0 | M21: =MOD(INT(D21/10),10) -> 0 | N21: =MOD(D21,10) -> 0 | O21: =INT(K21/4)+(J21*2)+(I21*16) -> 24 | P21: =(I21*4)+INT(J21/2) -> 6 | Q21: =V21 -> 0 | R21: =(MOD(L21,4)*100)+(M21*10)+N21 -> 0 | S21: =(MOD(K21,2)*2)+INT(L21/4) -> 0 | T21: =MOD(INT(K21/2),2) -> 0 | U21: =INT(J21/2) -> 2 | V21: =(MOD(J21,2)*2)+INT(K21/4) -> 0 | W21: =(MOD(K21,4)*2)+INT(L21/4) -> 0 | X21: =MOD(L21,4) -> 0 | Y21: =INT(M21/2) -> 0 | Z21: =MOD(M21,2) -> 0 | AA21: =N21 -> 0 | AB21: =IF(S21=0,AC21,IF(S21=1,IF(AD21="********",AF21,AD21),AF21&","&TEXT(S21,"0"))) -> 0 | AC21: =_xlfn.XLOOKUP(R21,Sheet2!$H$3:$H$258,Sheet2!$I$3:$I$258,"-----") -> 0 | AD21: =_xlfn.XLOOKUP(VALUE(AE21),Sheet2!$N$3:$N$1000,Sheet2!$O$3:$O$1000,"********") -> ******** | AE21: =IF(VALUE(AF21)<0,DEC2OCT(OCT2DEC(VALUE(C21))-OCT2DEC(-VALUE(AF21))),DEC2OCT(OCT2DEC(VALUE(C21))+OCT2DEC(VALUE(AF21)))) -> 56 | AF21: =IF(R21<200,"+"&TEXT(R21,"0"),"-"&TEXT(_xlfn.XLOOKUP(R21,Sheet2!$K$3:$K$130,Sheet2!$L$3:$L$130,"-----"),"0")) -> +0 | AG21: =IF(T21=1,"@","") | AH21: =IF(Q21=0,"JMP "&AJ21, IF(Q21=1,"JSR "&AJ21,IF(Q21=2,"ISZ "&AJ21,"DSZ "&AJ21))) -> JMP 0 | AI21: =TEXT(Q21,"0")&","&AG21&AB21 -> 0,0 | AJ21: =AG21&AB21 -> 0 | AK21: =AL21&AN21&AM21&AO21&" "&TEXT(U21,"0")&","&TEXT(V21,"0")&AP21 -> COM 2,0 | AL21: =IF(W21=0,"COM",IF(W21=1,"NEG",IF(W21=2,"MOV",IF(W21=3,"INC",IF(W21=4,"ADC",IF(W21=5,"SUB",IF(W21=6,"ADD","AND"))))))) -> COM | AM21: =IF(X21=0,"",IF(X21=1,"L",IF(X21=2,"R","S"))) | AN21: =IF(Y21=0,"",IF(Y21=1,"Z",IF(Y21=2,"O","C"))) | AO21: =IF(Z21=1,"#","") | AP21: =IF(AA21=0,"",IF(AA21=1,",SKP",IF(AA21=2,",SZC",IF(AA21=3,",SNC",IF(AA21=4,",SZR",IF(AA21=5,",SNR",IF(AA21=6,",SEZ",",SBN"))))))) | AQ21: =_xlfn.XLOOKUP(D21,Sheet2!$E$3:$E$101,Sheet2!$F$3:$F$101,"******************") -> ****************** | AR21: =IF(AY21=0,"NIO"&AV21&" "&AX21,IF(AY21=7,AZ21&" "&AX21,AS21&" "&TEXT(AT21,"0")&","&AX21)) -> NIO 0 | AS21: =IF(AY21=1,"DIA"&AV21,IF(AY21=2,"DOA"&AV21,IF(AY21=3,"DIB"&AV21,IF(AY21=4,"DOB"&AV21,IF(AY21=5,"DIC"&AV21,"DOC"&AV21))))) -> DOC | AT21: =V21 -> 0 | AU21: =X21 -> 0 | AV21: =IF(AU21=0,"",IF(AU21=1,"S",IF(AU21=2,"C","P"))) | AW21: =M21*10+N21 -> 0 | AX21: =_xlfn.XLOOKUP(AW21,Sheet2!$Q$3:$Q$66,Sheet2!$R$3:$R$66,"**") -> 0 | AY21: =W21 -> 0 | AZ21: =IF(AU21=0,"SKPBN",IF(AU21=1,"SKPBZ",IF(AU21=2,"SKPDN","SKPDZ"))) -> SKPBN
B22: =B21+1 -> 26 | C22: =IF(MOD(C21,10)=7,C21+3,C21+1) -> 57 | D22: 1 | E22: =_xlfn.XLOOKUP(C22,Sheet2!$N$3:$N$1000,Sheet2!$O$3:$O$1000,"") | G22: =DEC2OCT((2*(OCT2DEC(I22*100)+OCT2DEC(J22*10)+K22))+INT(L22/4)) -> 0 | H22: =(MOD(L22,4)*100)+(M22*10)+N22 -> 1 | I22: =MOD(INT(D22/100000),10) -> 0 | J22: =MOD(INT(D22/10000),10) -> 0 | K22: =MOD(INT(D22/1000),10) -> 0 | L22: =MOD(INT(D22/100),10) -> 0 | M22: =MOD(INT(D22/10),10) -> 0 | N22: =MOD(D22,10) -> 1 | O22: =INT(K22/4)+(J22*2)+(I22*16) -> 0 | P22: =(I22*4)+INT(J22/2) -> 0 | Q22: =V22 -> 0 | R22: =(MOD(L22,4)*100)+(M22*10)+N22 -> 1 | S22: =(MOD(K22,2)*2)+INT(L22/4) -> 0 | T22: =MOD(INT(K22/2),2) -> 0 | U22: =INT(J22/2) -> 0 | V22: =(MOD(J22,2)*2)+INT(K22/4) -> 0 | W22: =(MOD(K22,4)*2)+INT(L22/4) -> 0 | X22: =MOD(L22,4) -> 0 | Y22: =INT(M22/2) -> 0 | Z22: =MOD(M22,2) -> 0 | AA22: =N22 -> 1 | AB22: =IF(S22=0,AC22,IF(S22=1,IF(AD22="********",AF22,AD22),AF22&","&TEXT(S22,"0"))) -> 1 | AC22: =_xlfn.XLOOKUP(R22,Sheet2!$H$3:$H$258,Sheet2!$I$3:$I$258,"-----") -> 1 | AD22: =_xlfn.XLOOKUP(VALUE(AE22),Sheet2!$N$3:$N$1000,Sheet2!$O$3:$O$1000,"********") -> ******** | AE22: =IF(VALUE(AF22)<0,DEC2OCT(OCT2DEC(VALUE(C22))-OCT2DEC(-VALUE(AF22))),DEC2OCT(OCT2DEC(VALUE(C22))+OCT2DEC(VALUE(AF22)))) -> 60 | AF22: =IF(R22<200,"+"&TEXT(R22,"0"),"-"&TEXT(_xlfn.XLOOKUP(R22,Sheet2!$K$3:$K$130,Sheet2!$L$3:$L$130,"-----"),"0")) -> +1 | AG22: =IF(T22=1,"@","") | AH22: =IF(Q22=0,"JMP "&AJ22, IF(Q22=1,"JSR "&AJ22,IF(Q22=2,"ISZ "&AJ22,"DSZ "&AJ22))) -> JMP 1 | AI22: =TEXT(Q22,"0")&","&AG22&AB22 -> 0,1 | AJ22: =AG22&AB22 -> 1 | AK22: =AL22&AN22&AM22&AO22&" "&TEXT(U22,"0")&","&TEXT(V22,"0")&AP22 -> COM 0,0,SKP | AL22: =IF(W22=0,"COM",IF(W22=1,"NEG",IF(W22=2,"MOV",IF(W22=3,"INC",IF(W22=4,"ADC",IF(W22=5,"SUB",IF(W22=6,"ADD","AND"))))))) -> COM | AM22: =IF(X22=0,"",IF(X22=1,"L",IF(X22=2,"R","S"))) | AN22: =IF(Y22=0,"",IF(Y22=1,"Z",IF(Y22=2,"O","C"))) | AO22: =IF(Z22=1,"#","") | AP22: =IF(AA22=0,"",IF(AA22=1,",SKP",IF(AA22=2,",SZC",IF(AA22=3,",SNC",IF(AA22=4,",SZR",IF(AA22=5,",SNR",IF(AA22=6,",SEZ",",SBN"))))))) -> ,SKP | AQ22: =_xlfn.XLOOKUP(D22,Sheet2!$E$3:$E$101,Sheet2!$F$3:$F$101,"******************") -> ****************** | AR22: =IF(AY22=0,"NIO"&AV22&" "&AX22,IF(AY22=7,AZ22&" "&AX22,AS22&" "&TEXT(AT22,"0")&","&AX22)) -> NIO MDV | AS22: =IF(AY22=1,"DIA"&AV22,IF(AY22=2,"DOA"&AV22,IF(AY22=3,"DIB"&AV22,IF(AY22=4,"DOB"&AV22,IF(AY22=5,"DIC"&AV22,"DOC"&AV22))))) -> DOC | AT22: =V22 -> 0 | AU22: =X22 -> 0 | AV22: =IF(AU22=0,"",IF(AU22=1,"S",IF(AU22=2,"C","P"))) | AW22: =M22*10+N22 -> 1 | AX22: =_xlfn.XLOOKUP(AW22,Sheet2!$Q$3:$Q$66,Sheet2!$R$3:$R$66,"**") -> MDV | AY22: =W22 -> 0 | AZ22: =IF(AU22=0,"SKPBN",IF(AU22=1,"SKPBZ",IF(AU22=2,"SKPDN","SKPDZ"))) -> SKPBN
B23: =B22+1 -> 27 | C23: =IF(MOD(C22,10)=7,C22+3,C22+1) -> 60 | D23: 2 | E23: =_xlfn.XLOOKUP(C23,Sheet2!$N$3:$N$1000,Sheet2!$O$3:$O$1000,"") | G23: =DEC2OCT((2*(OCT2DEC(I23*100)+OCT2DEC(J23*10)+K23))+INT(L23/4)) -> 0 | H23: =(MOD(L23,4)*100)+(M23*10)+N23 -> 2 | I23: =MOD(INT(D23/100000),10) -> 0 | J23: =MOD(INT(D23/10000),10) -> 0 | K23: =MOD(INT(D23/1000),10) -> 0 | L23: =MOD(INT(D23/100),10) -> 0 | M23: =MOD(INT(D23/10),10) -> 0 | N23: =MOD(D23,10) -> 2 | O23: =INT(K23/4)+(J23*2)+(I23*16) -> 0 | P23: =(I23*4)+INT(J23/2) -> 0 | Q23: =V23 -> 0 | R23: =(MOD(L23,4)*100)+(M23*10)+N23 -> 2 | S23: =(MOD(K23,2)*2)+INT(L23/4) -> 0 | T23: =MOD(INT(K23/2),2) -> 0 | U23: =INT(J23/2) -> 0 | V23: =(MOD(J23,2)*2)+INT(K23/4) -> 0 | W23: =(MOD(K23,4)*2)+INT(L23/4) -> 0 | X23: =MOD(L23,4) -> 0 | Y23: =INT(M23/2) -> 0 | Z23: =MOD(M23,2) -> 0 | AA23: =N23 -> 2 | AB23: =IF(S23=0,AC23,IF(S23=1,IF(AD23="********",AF23,AD23),AF23&","&TEXT(S23,"0"))) -> ***** | AC23: =_xlfn.XLOOKUP(R23,Sheet2!$H$3:$H$258,Sheet2!$I$3:$I$258,"-----") -> ***** | AD23: =_xlfn.XLOOKUP(VALUE(AE23),Sheet2!$N$3:$N$1000,Sheet2!$O$3:$O$1000,"********") -> ******** | AE23: =IF(VALUE(AF23)<0,DEC2OCT(OCT2DEC(VALUE(C23))-OCT2DEC(-VALUE(AF23))),DEC2OCT(OCT2DEC(VALUE(C23))+OCT2DEC(VALUE(AF23)))) -> 62 | AF23: =IF(R23<200,"+"&TEXT(R23,"0"),"-"&TEXT(_xlfn.XLOOKUP(R23,Sheet2!$K$3:$K$130,Sheet2!$L$3:$L$130,"-----"),"0")) -> +2 | AG23: =IF(T23=1,"@","") | AH23: =IF(Q23=0,"JMP "&AJ23, IF(Q23=1,"JSR "&AJ23,IF(Q23=2,"ISZ "&AJ23,"DSZ "&AJ23))) -> JMP ***** | AI23: =TEXT(Q23,"0")&","&AG23&AB23 -> 0,***** | AJ23: =AG23&AB23 -> ***** | AK23: =AL23&AN23&AM23&AO23&" "&TEXT(U23,"0")&","&TEXT(V23,"0")&AP23 -> COM 0,0,SZC | AL23: =IF(W23=0,"COM",IF(W23=1,"NEG",IF(W23=2,"MOV",IF(W23=3,"INC",IF(W23=4,"ADC",IF(W23=5,"SUB",IF(W23=6,"ADD","AND"))))))) -> COM | AM23: =IF(X23=0,"",IF(X23=1,"L",IF(X23=2,"R","S"))) | AN23: =IF(Y23=0,"",IF(Y23=1,"Z",IF(Y23=2,"O","C"))) | AO23: =IF(Z23=1,"#","") | AP23: =IF(AA23=0,"",IF(AA23=1,",SKP",IF(AA23=2,",SZC",IF(AA23=3,",SNC",IF(AA23=4,",SZR",IF(AA23=5,",SNR",IF(AA23=6,",SEZ",",SBN"))))))) -> ,SZC | AQ23: =_xlfn.XLOOKUP(D23,Sheet2!$E$3:$E$101,Sheet2!$F$3:$F$101,"******************") -> ****************** | AR23: =IF(AY23=0,"NIO"&AV23&" "&AX23,IF(AY23=7,AZ23&" "&AX23,AS23&" "&TEXT(AT23,"0")&","&AX23)) -> NIO MAP0 | AS23: =IF(AY23=1,"DIA"&AV23,IF(AY23=2,"DOA"&AV23,IF(AY23=3,"DIB"&AV23,IF(AY23=4,"DOB"&AV23,IF(AY23=5,"DIC"&AV23,"DOC"&AV23))))) -> DOC | AT23: =V23 -> 0 | AU23: =X23 -> 0 | AV23: =IF(AU23=0,"",IF(AU23=1,"S",IF(AU23=2,"C","P"))) | AW23: =M23*10+N23 -> 2 | AX23: =_xlfn.XLOOKUP(AW23,Sheet2!$Q$3:$Q$66,Sheet2!$R$3:$R$66,"**") -> MAP0 | AY23: =W23 -> 0 | AZ23: =IF(AU23=0,"SKPBN",IF(AU23=1,"SKPBZ",IF(AU23=2,"SKPDN","SKPDZ"))) -> SKPBN
